Workbook
Name AnnoGestione: PARAMETRI!$B$11
Name ListaCommesseDashboard: PARAMETRI!$D$3:$D$303
Name ListaCommessePregresse: PARAMETRI!$F$4:$F$303
Name ListaCommessePregresseDashboard: PARAMETRI!$F$3:$F$303
Name ListaCommesseSelezione: ANAGRAFICA!$Q$6:$Q$305
Name ListaMesi: PARAMETRI!$G$3:$G$14
Name ListaTipiMovimento: PARAMETRI!$H$3:$H$9

Sheet ANAGRAFICA
A1: ANAGRAFICA COMMESSE — REV.14
A2: Unica fonte master. Utilizzare i filtri della tabella (tecnico e date): il conteggio delle commesse visibili si aggiorna automaticamente.
A3: COMMESSE TOTALI | B3: =COUNTA($B$6:$B$305) -> 4
A4: VISIBILI DOPO I FILTRI | B4: =SUBTOTAL(103,$B$6:$B$305) -> 3
A5: DATA DI INSERIMENTO * | B5: CODICE COMMESSA | C5: CLIENTE | D5: DESCRIZIONE / CANTIERE | E5: RAMO DI ATTIVITÀ | F5: TECNICO | G5: PREPOSTO | H5: DATA DI INIZIO PREVISTO | I5: DATA DI INIZIO EFFETTIVO | J5: DATA DI FINE PREVISTA | K5: DATA DI FINE EFFETTIVA | L5: STATO CANTIERE | M5: RITENUTE PREVISTE | N5: CONTRATTO INIZIALE | O5: INTEGRAZIONI | P5: CONTRATTO AGGIORNATO | Q5: CODICE | CLIENTE | CANTIERE | R5: CAUSA AGGIORNAMENTO DATA FINE | S5: CONTROLLO DUPLICAZIONE
B6: C042 | C6: CARRON BAU | D6: MURATURE IN LATERIZIO C/O COSMO SPA - PESCHIERA DEL GARDA | E6: MURATURA | F6: DAVIDE | G6: AHMET MOUSTAFA | I6: 46181 | J6: 46259 | L6: In corso | M6: SI | N6: 143061.41 | P6: =IF($B6="","",IF(AND($N6="",$O6=""),"",SUM($N6:$O6))) -> 143061.41 | Q6: =IF($B6="","",$B6&" | "&$C6&" | "&$D6) -> C042 | CARRON BAU | MURATURE IN LATERIZIO C/O COSMO SPA - PESCHIERA DEL GARDA | R6: Proroga/Sospensione autorizzata | S6: =IF($B6="","",IF(COUNTIF($B$6:$B$305,$B6)>1,"DUPLICATO","OK")) -> DUPLICATO | T6: 46249
B7: C011 | C7: CARRON | D7: ZABARELLA 2023 - COD. CANTIERE 774 | E7: MURATURA+ECONOMIE | F7: ALBAN | G7: NA | I7: 46037 | J7: 46112 | L7: Finito ritenute non previste | M7: NO | N7: 55228 | O7: 127530 | P7: =IF($B7="","",IF(AND($N7="",$O7=""),"",SUM($N7:$O7))) -> 182758 | Q7: =IF($B7="","",$B7&" | "&$C7&" | "&$D7) -> C011 | CARRON | ZABARELLA 2023 - COD. CANTIERE 774 | S7: =IF($B7="","",IF(COUNTIF($B$6:$B$305,$B7)>1,"DUPLICATO","OK")) -> OK | T7: 46112
B8: TEST10 | C8: COMMESSA DIMOSTRATIVA | D8: TEST REV.10 - PERDITE SAL E COSTI MENSILI | E8: TEST | F8: DIREZIONE | G8: PREPOSTO TEST | I8: 46023 | J8: 46387 | L8: In corso | M8: NO | N8: 100000 | O8: 0 | P8: =IF($B8="","",IF(AND($N8="",$O8=""),"",SUM($N8:$O8))) -> 100000 | Q8: =IF($B8="","",$B8&" | "&$C8&" | "&$D8) -> TEST10 | COMMESSA DIMOSTRATIVA | TEST REV.10 - PERDITE SAL E COSTI MENSILI | R8: Nessuna variazione | S8: =IF($B8="","",IF(COUNTIF($B$6:$B$305,$B8)>1,"DUPLICATO","OK")) -> OK | T8: 46387
B9: C042 | P9: =IF($B9="","",IF(AND($N9="",$O9=""),"",SUM($N9:$O9))) | Q9: =IF($B9="","",$B9&" | "&$C9&" | "&$D9) -> C042 | | | S9: =IF($B9="","",IF(COUNTIF($B$6:$B$305,$B9)>1,"DUPLICATO","OK")) -> DUPLICATO
P10: =IF($B10="","",IF(AND($N10="",$O10=""),"",SUM($N10:$O10))) | Q10: =IF($B10="","",$B10&" | "&$C10&" | "&$D10) | S10: =IF($B10="","",IF(COUNTIF($B$6:$B$305,$B10)>1,"DUPLICATO","OK"))
P11: =IF($B11="","",IF(AND($N11="",$O11=""),"",SUM($N11:$O11))) | Q11: =IF($B11="","",$B11&" | "&$C11&" | "&$D11) | S11: =IF($B11="","",IF(COUNTIF($B$6:$B$305,$B11)>1,"DUPLICATO","OK"))
P12: =IF($B12="","",IF(AND($N12="",$O12=""),"",SUM($N12:$O12))) | Q12: =IF($B12="","",$B12&" | "&$C12&" | "&$D12) | S12: =IF($B12="","",IF(COUNTIF($B$6:$B$305,$B12)>1,"DUPLICATO","OK"))
P13: =IF($B13="","",IF(AND($N13="",$O13=""),"",SUM($N13:$O13))) | Q13: =IF($B13="","",$B13&" | "&$C13&" | "&$D13) | S13: =IF($B13="","",IF(COUNTIF($B$6:$B$305,$B13)>1,"DUPLICATO","OK"))
P14: =IF($B14="","",IF(AND($N14="",$O14=""),"",SUM($N14:$O14))) | Q14: =IF($B14="","",$B14&" | "&$C14&" | "&$D14) | S14: =IF($B14="","",IF(COUNTIF($B$6:$B$305,$B14)>1,"DUPLICATO","OK"))
P15: =IF($B15="","",IF(AND($N15="",$O15=""),"",SUM($N15:$O15))) | Q15: =IF($B15="","",$B15&" | "&$C15&" | "&$D15) | S15: =IF($B15="","",IF(COUNTIF($B$6:$B$305,$B15)>1,"DUPLICATO","OK"))
P16: =IF($B16="","",IF(AND($N16="",$O16=""),"",SUM($N16:$O16))) | Q16: =IF($B16="","",$B16&" | "&$C16&" | "&$D16) | S16: =IF($B16="","",IF(COUNTIF($B$6:$B$305,$B16)>1,"DUPLICATO","OK"))
P17: =IF($B17="","",IF(AND($N17="",$O17=""),"",SUM($N17:$O17))) | Q17: =IF($B17="","",$B17&" | "&$C17&" | "&$D17) | S17: =IF($B17="","",IF(COUNTIF($B$6:$B$305,$B17)>1,"DUPLICATO","OK"))
P18: =IF($B18="","",IF(AND($N18="",$O18=""),"",SUM($N18:$O18))) | Q18: =IF($B18="","",$B18&" | "&$C18&" | "&$D18) | S18: =IF($B18="","",IF(COUNTIF($B$6:$B$305,$B18)>1,"DUPLICATO","OK"))
P19: =IF($B19="","",IF(AND($N19="",$O19=""),"",SUM($N19:$O19))) | Q19: =IF($B19="","",$B19&" | "&$C19&" | "&$D19) | S19: =IF($B19="","",IF(COUNTIF($B$6:$B$305,$B19)>1,"DUPLICATO","OK"))
P20: =IF($B20="","",IF(AND($N20="",$O20=""),"",SUM($N20:$O20))) | Q20: =IF($B20="","",$B20&" | "&$C20&" | "&$D20) | S20: =IF($B20="","",IF(COUNTIF($B$6:$B$305,$B20)>1,"DUPLICATO","OK"))
P21: =IF($B21="","",IF(AND($N21="",$O21=""),"",SUM($N21:$O21))) | Q21: =IF($B21="","",$B21&" | "&$C21&" | "&$D21) | S21: =IF($B21="","",IF(COUNTIF($B$6:$B$305,$B21)>1,"DUPLICATO","OK"))
... P305: =IF($B305="","",IF(AND($N305="",$O305=""),"",SUM($N305:$O305))) | Q305: =IF($B305="","",$B305&" | "&$C305&" | "&$D305) | S305: =IF($B305="","",IF(COUNTIF($B$6:$B$305,$B305)>1,"DUPLICATO","OK"))

Sheet SALDI AL 31.12.2025
A1: SALDI AL 31.12.2025 — REV.14
A2: COMMESSA | C2: SAL MATURATO | D2: FATTURATO LORDO | E2: RITENUTE | F2: SVINCOLI | G2: PERDITE SAL | H2: ORE | I2: COSTI DIRETTI | J2: RIGHE
A3: TUTTE | C3: =IF($A$3="TUTTE",SUM($C$6:$C$505),SUMIF($A$6:$A$505,$A$3,$C$6:$C$505)) -> 0 | D3: =IF($A$3="TUTTE",SUM($D$6:$D$505),SUMIF($A$6:$A$505,$A$3,$D$6:$D$505)) -> 0 | E3: =IF($A$3="TUTTE",SUM($E$6:$E$505),SUMIF($A$6:$A$505,$A$3,$E$6:$E$505)) -> 0 | F3: =IF($A$3="TUTTE",SUM($F$6:$F$505),SUMIF($A$6:$A$505,$A$3,$F$6:$F$505)) -> 0 | G3: =IF($A$3="TUTTE",SUM($G$6:$G$505),SUMIF($A$6:$A$505,$A$3,$G$6:$G$505)) -> 0 | H3: =IF($A$3="TUTTE",SUM($H$6:$H$505),SUMIF($A$6:$A$505,$A$3,$H$6:$H$505)) -> 0 | I3: =IF($A$3="TUTTE",SUM($I$6:$I$505),SUMIF($A$6:$A$505,$A$3,$I$6:$I$505)) -> 0 | J3: =IF($A$3="TUTTE",COUNTIF($A$6:$A$505,"<>"),COUNTIF($A$6:$A$505,$A$3)) -> 0
A5: CODICE COMMESSA | B5: DATA SALDO | C5: SAL MATURATO | D5: FATTURATO LORDO | E5: RITENUTE | F5: SVINCOLI | G5: PERDITE SAL ACCETTATE | H5: ORE | I5: COSTI DIRETTI | J5: CONTROLLO DUPLICATO
B6: =IF($A6="","",DATE(PARAMETRI!$B$11-1,12,31)) | J6: =IF($A6="","",IF(COUNTIF($A$6:$A$505,$A6)>1,"DUPLICATO","OK"))
B7: =IF($A7="","",DATE(PARAMETRI!$B$11-1,12,31)) | J7: =IF($A7="","",IF(COUNTIF($A$6:$A$505,$A7)>1,"DUPLICATO","OK"))
B8: =IF($A8="","",DATE(PARAMETRI!$B$11-1,12,31)) | J8: =IF($A8="","",IF(COUNTIF($A$6:$A$505,$A8)>1,"DUPLICATO","OK"))
B9: =IF($A9="","",DATE(PARAMETRI!$B$11-1,12,31)) | J9: =IF($A9="","",IF(COUNTIF($A$6:$A$505,$A9)>1,"DUPLICATO","OK"))
B10: =IF($A10="","",DATE(PARAMETRI!$B$11-1,12,31)) | J10: =IF($A10="","",IF(COUNTIF($A$6:$A$505,$A10)>1,"DUPLICATO","OK"))
B11: =IF($A11="","",DATE(PARAMETRI!$B$11-1,12,31)) | J11: =IF($A11="","",IF(COUNTIF($A$6:$A$505,$A11)>1,"DUPLICATO","OK"))
B12: =IF($A12="","",DATE(PARAMETRI!$B$11-1,12,31)) | J12: =IF($A12="","",IF(COUNTIF($A$6:$A$505,$A12)>1,"DUPLICATO","OK"))
B13: =IF($A13="","",DATE(PARAMETRI!$B$11-1,12,31)) | J13: =IF($A13="","",IF(COUNTIF($A$6:$A$505,$A13)>1,"DUPLICATO","OK"))
B14: =IF($A14="","",DATE(PARAMETRI!$B$11-1,12,31)) | J14: =IF($A14="","",IF(COUNTIF($A$6:$A$505,$A14)>1,"DUPLICATO","OK"))
B15: =IF($A15="","",DATE(PARAMETRI!$B$11-1,12,31)) | J15: =IF($A15="","",IF(COUNTIF($A$6:$A$505,$A15)>1,"DUPLICATO","OK"))
B16: =IF($A16="","",DATE(PARAMETRI!$B$11-1,12,31)) | J16: =IF($A16="","",IF(COUNTIF($A$6:$A$505,$A16)>1,"DUPLICATO","OK"))
B17: =IF($A17="","",DATE(PARAMETRI!$B$11-1,12,31)) | J17: =IF($A17="","",IF(COUNTIF($A$6:$A$505,$A17)>1,"DUPLICATO","OK"))
... B505: =IF($A505="","",DATE(PARAMETRI!$B$11-1,12,31)) | J505: =IF($A505="","",IF(COUNTIF($A$6:$A$505,$A505)>1,"DUPLICATO","OK"))

Sheet BUDGET COMMESSA
A1: BUDGET COMMESSA — REV.14
A2: Budget tecnico per commessa. Codice, cliente e cantiere provengono esclusivamente dall'ANAGRAFICA.
A3: PERIODO DA | B3: 46023 | C3: PERIODO A | D3: 46387 | E3: COMMESSE APERTE | F3: =IF(OR($B$3="",$D$3="",$B$3>$D$3),"",COUNTIFS(ANAGRAFICA!$J$6:$J$305,">="&$B$3,ANAGRAFICA!$J$6:$J$305,"<="&$D$3,ANAGRAFICA!$K$6:$K$305,"",ANAGRAFICA!$L$6:$L$305,"<>Finito*",ANAGRAFICA!$B$6:$B$305,"<>")) -> 2 | G3: ORE PREVISTE | H3: =IF(OR($B$3="",$D$3="",$B$3>$D$3),"",SUMIFS($D$6:$D$305,ANAGRAFICA!$J$6:$J$305,">="&$B$3,ANAGRAFICA!$J$6:$J$305,"<="&$D$3,ANAGRAFICA!$K$6:$K$305,"",ANAGRAFICA!$L$6:$L$305,"<>Finito*",ANAGRAFICA!$B$6:$B$305,"<>")) -> 2800 | I3: COSTO TOTALE PREVISTO | J3: =IF(OR($B$3="",$D$3="",$B$3>$D$3),"",SUMIFS($H$6:$H$305,ANAGRAFICA!$J$6:$J$305,">="&$B$3,ANAGRAFICA!$J$6:$J$305,"<="&$D$3,ANAGRAFICA!$K$6:$K$305,"",ANAGRAFICA!$L$6:$L$305,"<>Finito*",ANAGRAFICA!$B$6:$B$305,"<>")) -> 179520
A4: La dashboard considera le commesse ancora aperte con DATA DI FINE PREVISTA compresa nel periodo selezionato.
A5: CODICE COMMESSA | B5: CLIENTE | C5: DESCRIZIONE / CANTIERE | D5: ORE PREVISTE | E5: COSTO ORARIO | F5: COSTO ORE | G5: COSTI DIRETTI PREVISTI | H5: COSTO TOTALE PREVISTO | I5: MARGINE TEORICO | J5: NOTE
A6: =IF(ANAGRAFICA!$B6="","",ANAGRAFICA!$B6) -> C042 | B6: =IF($A6="","",ANAGRAFICA!$C6) -> CARRON BAU | C6: =IF($A6="","",ANAGRAFICA!$D6) -> MURATURE IN LATERIZIO C/O COSMO SPA - PESCHIERA DEL GARDA | D6: 1800 | E6: 45.79 | F6: =IF(OR($A6="",$D6="",$E6=""),"",$D6*$E6) -> 82422 | G6: 31308 | H6: =IF($A6="","",SUM($F6,$G6)) -> 113730 | I6: =IFERROR(IF(OR($A6="",ANAGRAFICA!$P6="",ANAGRAFICA!$P6=0),"",(ANAGRAFICA!$P6-$H6)/ANAGRAFICA!$P6),"") -> 0.20502671 | J6: DATI DIMOSTRATIVI — da sostituire con l'Analisi di fattibilità approvata
A7: =IF(ANAGRAFICA!$B7="","",ANAGRAFICA!$B7) -> C011 | B7: =IF($A7="","",ANAGRAFICA!$C7) -> CARRON | C7: =IF($A7="","",ANAGRAFICA!$D7) -> ZABARELLA 2023 - COD. CANTIERE 774 | F7: =IF(OR($A7="",$D7="",$E7=""),"",$D7*$E7) | H7: =IF($A7="","",SUM($F7,$G7)) -> 0 | I7: =IFERROR(IF(OR($A7="",ANAGRAFICA!$P7="",ANAGRAFICA!$P7=0),"",(ANAGRAFICA!$P7-$H7)/ANAGRAFICA!$P7),"") -> 1
A8: =IF(ANAGRAFICA!$B8="","",ANAGRAFICA!$B8) -> TEST10 | B8: =IF($A8="","",ANAGRAFICA!$C8) -> COMMESSA DIMOSTRATIVA | C8: =IF($A8="","",ANAGRAFICA!$D8) -> TEST REV.10 - PERDITE SAL E COSTI MENSILI | D8: 1000 | E8: 45.79 | F8: =IF(OR($A8="",$D8="",$E8=""),"",$D8*$E8) -> 45790 | G8: 20000 | H8: =IF($A8="","",SUM($F8,$G8)) -> 65790 | I8: =IFERROR(IF(OR($A8="",ANAGRAFICA!$P8="",ANAGRAFICA!$P8=0),"",(ANAGRAFICA!$P8-$H8)/ANAGRAFICA!$P8),"") -> 0.3421
A9: =IF(ANAGRAFICA!$B9="","",ANAGRAFICA!$B9) -> C042 | B9: =IF($A9="","",ANAGRAFICA!$C9) -> 0 | C9: =IF($A9="","",ANAGRAFICA!$D9) -> 0 | F9: =IF(OR($A9="",$D9="",$E9=""),"",$D9*$E9) | H9: =IF($A9="","",SUM($F9,$G9)) -> 0 | I9: =IFERROR(IF(OR($A9="",ANAGRAFICA!$P9="",ANAGRAFICA!$P9=0),"",(ANAGRAFICA!$P9-$H9)/ANAGRAFICA!$P9),"")
A10: =IF(ANAGRAFICA!$B10="","",ANAGRAFICA!$B10) | B10: =IF($A10="","",ANAGRAFICA!$C10) | C10: =IF($A10="","",ANAGRAFICA!$D10) | F10: =IF(OR($A10="",$D10="",$E10=""),"",$D10*$E10) | H10: =IF($A10="","",SUM($F10,$G10)) | I10: =IFERROR(IF(OR($A10="",ANAGRAFICA!$P10="",ANAGRAFICA!$P10=0),"",(ANAGRAFICA!$P10-$H10)/ANAGRAFICA!$P10),"")
A11: =IF(ANAGRAFICA!$B11="","",ANAGRAFICA!$B11) | B11: =IF($A11="","",ANAGRAFICA!$C11) | C11: =IF($A11="","",ANAGRAFICA!$D11) | F11: =IF(OR($A11="",$D11="",$E11=""),"",$D11*$E11) | H11: =IF($A11="","",SUM($F11,$G11)) | I11: =IFERROR(IF(OR($A11="",ANAGRAFICA!$P11="",ANAGRAFICA!$P11=0),"",(ANAGRAFICA!$P11-$H11)/ANAGRAFICA!$P11),"")
A12: =IF(ANAGRAFICA!$B12="","",ANAGRAFICA!$B12) | B12: =IF($A12="","",ANAGRAFICA!$C12) | C12: =IF($A12="","",ANAGRAFICA!$D12) | F12: =IF(OR($A12="",$D12="",$E12=""),"",$D12*$E12) | H12: =IF($A12="","",SUM($F12,$G12)) | I12: =IFERROR(IF(OR($A12="",ANAGRAFICA!$P12="",ANAGRAFICA!$P12=0),"",(ANAGRAFICA!$P12-$H12)/ANAGRAFICA!$P12),"")
A13: =IF(ANAGRAFICA!$B13="","",ANAGRAFICA!$B13) | B13: =IF($A13="","",ANAGRAFICA!$C13) | C13: =IF($A13="","",ANAGRAFICA!$D13) | F13: =IF(OR($A13="",$D13="",$E13=""),"",$D13*$E13) | H13: =IF($A13="","",SUM($F13,$G13)) | I13: =IFERROR(IF(OR($A13="",ANAGRAFICA!$P13="",ANAGRAFICA!$P13=0),"",(ANAGRAFICA!$P13-$H13)/ANAGRAFICA!$P13),"")
A14: =IF(ANAGRAFICA!$B14="","",ANAGRAFICA!$B14) | B14: =IF($A14="","",ANAGRAFICA!$C14) | C14: =IF($A14="","",ANAGRAFICA!$D14) | F14: =IF(OR($A14="",$D14="",$E14=""),"",$D14*$E14) | H14: =IF($A14="","",SUM($F14,$G14)) | I14: =IFERROR(IF(OR($A14="",ANAGRAFICA!$P14="",ANAGRAFICA!$P14=0),"",(ANAGRAFICA!$P14-$H14)/ANAGRAFICA!$P14),"")
A15: =IF(ANAGRAFICA!$B15="","",ANAGRAFICA!$B15) | B15: =IF($A15="","",ANAGRAFICA!$C15) | C15: =IF($A15="","",ANAGRAFICA!$D15) | F15: =IF(OR($A15="",$D15="",$E15=""),"",$D15*$E15) | H15: =IF($A15="","",SUM($F15,$G15)) | I15: =IFERROR(IF(OR($A15="",ANAGRAFICA!$P15="",ANAGRAFICA!$P15=0),"",(ANAGRAFICA!$P15-$H15)/ANAGRAFICA!$P15),"")
A16: =IF(ANAGRAFICA!$B16="","",ANAGRAFICA!$B16) | B16: =IF($A16="","",ANAGRAFICA!$C16) | C16: =IF($A16="","",ANAGRAFICA!$D16) | F16: =IF(OR($A16="",$D16="",$E16=""),"",$D16*$E16) | H16: =IF($A16="","",SUM($F16,$G16)) | I16: =IFERROR(IF(OR($A16="",ANAGRAFICA!$P16="",ANAGRAFICA!$P16=0),"",(ANAGRAFICA!$P16-$H16)/ANAGRAFICA!$P16),"")
A17: =IF(ANAGRAFICA!$B17="","",ANAGRAFICA!$B17) | B17: =IF($A17="","",ANAGRAFICA!$C17) | C17: =IF($A17="","",ANAGRAFICA!$D17) | F17: =IF(OR($A17="",$D17="",$E17=""),"",$D17*$E17) | H17: =IF($A17="","",SUM($F17,$G17)) | I17: =IFERROR(IF(OR($A17="",ANAGRAFICA!$P17="",ANAGRAFICA!$P17=0),"",(ANAGRAFICA!$P17-$H17)/ANAGRAFICA!$P17),"")
A18: =IF(ANAGRAFICA!$B18="","",ANAGRAFICA!$B18) | B18: =IF($A18="","",ANAGRAFICA!$C18) | C18: =IF($A18="","",ANAGRAFICA!$D18) | F18: =IF(OR($A18="",$D18="",$E18=""),"",$D18*$E18) | H18: =IF($A18="","",SUM($F18,$G18)) | I18: =IFERROR(IF(OR($A18="",ANAGRAFICA!$P18="",ANAGRAFICA!$P18=0),"",(ANAGRAFICA!$P18-$H18)/ANAGRAFICA!$P18),"")
A19: =IF(ANAGRAFICA!$B19="","",ANAGRAFICA!$B19) | B19: =IF($A19="","",ANAGRAFICA!$C19) | C19: =IF($A19="","",ANAGRAFICA!$D19) | F19: =IF(OR($A19="",$D19="",$E19=""),"",$D19*$E19) | H19: =IF($A19="","",SUM($F19,$G19)) | I19: =IFERROR(IF(OR($A19="",ANAGRAFICA!$P19="",ANAGRAFICA!$P19=0),"",(ANAGRAFICA!$P19-$H19)/ANAGRAFICA!$P19),"")
A20: =IF(ANAGRAFICA!$B20="","",ANAGRAFICA!$B20) | B20: =IF($A20="","",ANAGRAFICA!$C20) | C20: =IF($A20="","",ANAGRAFICA!$D20) | F20: =IF(OR($A20="",$D20="",$E20=""),"",$D20*$E20) | H20: =IF($A20="","",SUM($F20,$G20)) | I20: =IFERROR(IF(OR($A20="",ANAGRAFICA!$P20="",ANAGRAFICA!$P20=0),"",(ANAGRAFICA!$P20-$H20)/ANAGRAFICA!$P20),"")
... A305: =IF(ANAGRAFICA!$B305="","",ANAGRAFICA!$B305) | B305: =IF($A305="","",ANAGRAFICA!$C305) | C305: =IF($A305="","",ANAGRAFICA!$D305) | F305: =IF(OR($A305="",$D305="",$E305=""),"",$D305*$E305) | H305: =IF($A305="","",SUM($F305,$G305)) | I305: =IFERROR(IF(OR($A305="",ANAGRAFICA!$P305="",ANAGRAFICA!$P305=0),"",(ANAGRAFICA!$P305-$H305)/ANAGRAFICA!$P305),"")

Sheet MOVIMENTI 2026
A1: MOVIMENTI 2026 — ARCHIVIO UNICO — REV.14
A2: COMMESSA | C2: MESE INIZIALE | E2: MESE FINALE | G2: SAL MATURATO | H2: FATTURATO LORDO | I2: RITENUTE | J2: SVINCOLI | K2: FATTURATO NETTO | L2: ORE | M2: PERDITE SAL | N2: COSTI DIRETTI | Q2: =DATE(PARAMETRI!$B$11,MATCH($C$3,PARAMETRI!$G$3:$G$14,0),1) -> 46023
A3: TUTTE | C3: Gennaio | E3: Dicembre | G3: =IF($Q$2>=$Q$3,0,IF($A$3="TUTTE",SUMIFS($I$7:$I$4206,$E$7:$E$4206,">="&$Q$2,$E$7:$E$4206,"<"&$Q$3),SUMIFS($I$7:$I$4206,$B$7:$B$4206,$A$3,$E$7:$E$4206,">="&$Q$2,$E$7:$E$4206,"<"&$Q$3))) -> 87770.9 | H3: =IF($Q$2>=$Q$3,0,IF($A$3="TUTTE",SUMIFS($J$7:$J$4206,$E$7:$E$4206,">="&$Q$2,$E$7:$E$4206,"<"&$Q$3),SUMIFS($J$7:$J$4206,$B$7:$B$4206,$A$3,$E$7:$E$4206,">="&$Q$2,$E$7:$E$4206,"<"&$Q$3))) -> 91770.9 | I3: =IF($Q$2>=$Q$3,0,IF($A$3="TUTTE",SUMIFS($K$7:$K$4206,$E$7:$E$4206,">="&$Q$2,$E$7:$E$4206,"<"&$Q$3),SUMIFS($K$7:$K$4206,$B$7:$B$4206,$A$3,$E$7:$E$4206,">="&$Q$2,$E$7:$E$4206,"<"&$Q$3))) -> 2010.23 | J3: =IF($Q$2>=$Q$3,0,IF($A$3="TUTTE",SUMIFS($L$7:$L$4206,$E$7:$E$4206,">="&$Q$2,$E$7:$E$4206,"<"&$Q$3),SUMIFS($L$7:$L$4206,$B$7:$B$4206,$A$3,$E$7:$E$4206,">="&$Q$2,$E$7:$E$4206,"<"&$Q$3))) -> 500 | K3: =IF($Q$2>=$Q$3,0,IF($A$3="TUTTE",SUMIFS($M$7:$M$4206,$E$7:$E$4206,">="&$Q$2,$E$7:$E$4206,"<"&$Q$3),SUMIFS($M$7:$M$4206,$B$7:$B$4206,$A$3,$E$7:$E$4206,">="&$Q$2,$E$7:$E$4206,"<"&$Q$3))) -> 90260.67 | L3: =IF($Q$2>=$Q$3,0,IF($A$3="TUTTE",SUMIFS($N$7:$N$4206,$E$7:$E$4206,">="&$Q$2,$E$7:$E$4206,"<"&$Q$3),SUMIFS($N$7:$N$4206,$B$7:$B$4206,$A$3,$E$7:$E$4206,">="&$Q$2,$E$7:$E$4206,"<"&$Q$3))) -> 980 | M3: =IF($Q$2>=$Q$3,0,IF($A$3="TUTTE",SUMIFS($P$7:$P$4206,$E$7:$E$4206,">="&$Q$2,$E$7:$E$4206,"<"&$Q$3),SUMIFS($P$7:$P$4206,$B$7:$B$4206,$A$3,$E$7:$E$4206,">="&$Q$2,$E$7:$E$4206,"<"&$Q$3))) -> 8000 | N3: =0+IF(MATCH($C$3,PARAMETRI!$G$3:$G$14,0)>MATCH($E$3,PARAMETRI!$G$3:$G$14,0),0,IF($A$3="TUTTE",SUMIFS('COSTI DIRETTI'!$H$6:$H$505,'COSTI DIRETTI'!$A$6:$A$505,">="&DATE(PARAMETRI!$B$11,MATCH($C$3,PARAMETRI!$G$3:$G$14,0),1),'COSTI DIRETTI'!$A$6:$A$505,"<"&DATE(PARAMETRI!$B$11,MATCH($E$3,PARAMETRI!$G$3:$G$14,0)+1,1)),SUMIFS('COSTI DIRETTI'!$H$6:$H$505,'COSTI DIRETTI'!$C$6:$C$505,$A$3,'COSTI DIRETTI'!$A$6:$A$505,">="&DATE(PARAMETRI!$B$11,MATCH($C$3,PARAMETRI!$G$3:$G$14,0),1),'COSTI DIRETTI'!$A$6:$A$505,"<"&DATE(PARAMETRI!$B$11,MATCH($E$3,PARAMETRI!$G$3:$G$14,0)+1,1)))) -> 38308 | Q3: =DATE(PARAMETRI!$B$11,MATCH($E$3,PARAMETRI!$G$3:$G$14,0)+1,1) -> 46388
A4: Dashboard = soli movimenti dell'anno corrente. I saldi al 31/12/2025 restano esclusi. Filtrare la tabella sottostante per analisi di dettaglio.
A6: COMMESSA (CODICE | CLIENTE | CANTIERE) | B6: CODICE COMMESSA | C6: CLIENTE | D6: CANTIERE | E6: DATA MOVIMENTO * | F6: TIPO MOVIMENTO | G6: NUMERO DOCUMENTO | H6: DESCRIZIONE | I6: SAL MATURATO | J6: FATTURATO LORDO | K6: RITENUTA | L6: SVINCOLO RITENUTA | M6: FATTURATO NETTO | N6: ORE EFFETTIVE | O6: NOTE | P6: PERDITA SAL ACCETTATA | Q6: MESE
A7: TEST10 | COMMESSA DIMOSTRATIVA | TEST REV.10 - PERDITE SAL E COSTI MENSILI | B7: =IFERROR(IF($A7="","",LEFT($A7,FIND(" | ",$A7)-1)),"") -> TEST10 | C7: =IFERROR(IF($A7="","",MID($A7,FIND(" | ",$A7)+3,FIND(" | ",$A7,FIND(" | ",$A7)+3)-FIND(" | ",$A7)-3)),"") -> COMMESSA DIMOSTRATIVA | D7: =IFERROR(IF($A7="","",RIGHT($A7,LEN($A7)-FIND(" | ",$A7,FIND(" | ",$A7)+3)-2)),"") -> TEST REV.10 - PERDITE SAL E COSTI MENSILI | E7: 46037 | F7: SAL + FATTURA | G7: T10-01 | H7: SAL/Fattura test gennaio | I7: 10000 | J7: 15000 | K7: 0 | L7: 0 | M7: =IF($B7="","",SUM($J7,-$K7,$L7)) -> 15000 | N7: 100 | O7: TEST REV.10 - MESE 1 | P7: 0
A8: TEST10 | COMMESSA DIMOSTRATIVA | TEST REV.10 - PERDITE SAL E COSTI MENSILI | B8: =IFERROR(IF($A8="","",LEFT($A8,FIND(" | ",$A8)-1)),"") -> TEST10 | C8: =IFERROR(IF($A8="","",MID($A8,FIND(" | ",$A8)+3,FIND(" | ",$A8,FIND(" | ",$A8)+3)-FIND(" | ",$A8)-3)),"") -> COMMESSA DIMOSTRATIVA | D8: =IFERROR(IF($A8="","",RIGHT($A8,LEN($A8)-FIND(" | ",$A8,FIND(" | ",$A8)+3)-2)),"") -> TEST REV.10 - PERDITE SAL E COSTI MENSILI | E8: 46068 | F8: SAL + FATTURA | G8: T10-02 | H8: SAL/Fattura e perdita accettata | I8: 10000 | J8: 15000 | K8: 0 | L8: 0 | M8: =IF($B8="","",SUM($J8,-$K8,$L8)) -> 15000 | N8: 120 | O8: TEST REV.10 - PERDITA DEFINITIVA | P8: 5000
A9: TEST10 | COMMESSA DIMOSTRATIVA | TEST REV.10 - PERDITE SAL E COSTI MENSILI | B9: =IFERROR(IF($A9="","",LEFT($A9,FIND(" | ",$A9)-1)),"") -> TEST10 | C9: =IFERROR(IF($A9="","",MID($A9,FIND(" | ",$A9)+3,FIND(" | ",$A9,FIND(" | ",$A9)+3)-FIND(" | ",$A9)-3)),"") -> COMMESSA DIMOSTRATIVA | D9: =IFERROR(IF($A9="","",RIGHT($A9,LEN($A9)-FIND(" | ",$A9,FIND(" | ",$A9)+3)-2)),"") -> TEST REV.10 - PERDITE SAL E COSTI MENSILI | E9: 46096 | F9: SAL + FATTURA | G9: T10-03 | H9: SAL/Fattura test marzo | I9: 5000 | J9: 10000 | K9: 0 | L9: 0 | M9: =IF($B9="","",SUM($J9,-$K9,$L9)) -> 10000 | N9: 80 | O9: TEST REV.10 - MESE 3 | P9: 0
A10: C042 | CARRON BAU | MURATURE IN LATERIZIO C/O COSMO SPA - PESCHIERA DEL GARDA | B10: =IFERROR(IF($A10="","",LEFT($A10,FIND(" | ",$A10)-1)),"") -> C042 | C10: =IFERROR(IF($A10="","",MID($A10,FIND(" | ",$A10)+3,FIND(" | ",$A10,FIND(" | ",$A10)+3)-FIND(" | ",$A10)-3)),"") -> CARRON BAU | D10: =IFERROR(IF($A10="","",RIGHT($A10,LEN($A10)-FIND(" | ",$A10,FIND(" | ",$A10)+3)-2)),"") -> MURATURE IN LATERIZIO C/O COSMO SPA - PESCHIERA DEL GARDA | E10: 46218 | F10: SAL + FATTURA | G10: 210 | H10: SAL 1 | I10: 20000 | J10: 18000 | K10: 900 | L10: 0 | M10: =IF($B10="","",SUM($J10,-$K10,$L10)) -> 17100 | N10: 300 | O10: PRIMO MOVIMENTO DI PROVA | P10: 2000
A11: C042 | CARRON BAU | MURATURE IN LATERIZIO C/O COSMO SPA - PESCHIERA DEL GARDA | B11: =IFERROR(IF($A11="","",LEFT($A11,FIND(" | ",$A11)-1)),"") -> C042 | C11: =IFERROR(IF($A11="","",MID($A11,FIND(" | ",$A11)+3,FIND(" | ",$A11,FIND(" | ",$A11)+3)-FIND(" | ",$A11)-3)),"") -> CARRON BAU | D11: =IFERROR(IF($A11="","",RIGHT($A11,LEN($A11)-FIND(" | ",$A11,FIND(" | ",$A11)+3)-2)),"") -> MURATURE IN LATERIZIO C/O COSMO SPA - PESCHIERA DEL GARDA | E11: 46234 | F11: SAL + FATTURA | G11: 259 | H11: SAL 2 | I11: 22770.9 | J11: 24770.9 | K11: 1110.23 | L11: 0 | M11: =IF($B11="","",SUM($J11,-$K11,$L11)) -> 23660.67 | N11: 380 | O11: SECONDO MOVIMENTO DELLA STESSA COMMESSA
A12: C011 | CARRON | ZABARELLA 2023 - COD. CANTIERE 774 | B12: =IFERROR(IF($A12="","",LEFT($A12,FIND(" | ",$A12)-1)),"") -> C011 | C12: =IFERROR(IF($A12="","",MID($A12,FIND(" | ",$A12)+3,FIND(" | ",$A12,FIND(" | ",$A12)+3)-FIND(" | ",$A12)-3)),"") -> CARRON | D12: =IFERROR(IF($A12="","",RIGHT($A12,LEN($A12)-FIND(" | ",$A12,FIND(" | ",$A12)+3)-2)),"") -> ZABARELLA 2023 - COD. CANTIERE 774 | E12: 46234 | I12: 10000 | J12: 9000 | M12: =IF($B12="","",SUM($J12,-$K12,$L12)) -> 9000 | P12: 1000
A13: C011 | CARRON | ZABARELLA 2023 - COD. CANTIERE 774 | B13: =IFERROR(IF($A13="","",LEFT($A13,FIND(" | ",$A13)-1)),"") -> C011 | C13: =IFERROR(IF($A13="","",MID($A13,FIND(" | ",$A13)+3,FIND(" | ",$A13,FIND(" | ",$A13)+3)-FIND(" | ",$A13)-3)),"") -> CARRON | D13: =IFERROR(IF($A13="","",RIGHT($A13,LEN($A13)-FIND(" | ",$A13,FIND(" | ",$A13)+3)-2)),"") -> ZABARELLA 2023 - COD. CANTIERE 774 | E13: 46234 | I13: 10000 | M13: =IF($B13="","",SUM($J13,-$K13,$L13)) -> 0
A14: C042 | CARRON BAU | MURATURE IN LATERIZIO C/O COSMO SPA - PESCHIERA DEL GARDA | B14: =IFERROR(IF($A14="","",LEFT($A14,FIND(" | ",$A14)-1)),"") -> C042 | C14: =IFERROR(IF($A14="","",MID($A14,FIND(" | ",$A14)+3,FIND(" | ",$A14,FIND(" | ",$A14)+3)-FIND(" | ",$A14)-3)),"") -> CARRON BAU | D14: =IFERROR(IF($A14="","",RIGHT($A14,LEN($A14)-FIND(" | ",$A14,FIND(" | ",$A14)+3)-2)),"") -> MURATURE IN LATERIZIO C/O COSMO SPA - PESCHIERA DEL GARDA | E14: 46259 | F14: SVINCOLO RITENUTA | G14: SV-01 | H14: SVINCOLO PARZIALE | I14: 0 | J14: 0 | K14: 0 | L14: 500 | M14: =IF($B14="","",SUM($J14,-$K14,$L14)) -> 500 | N14: 0 | O14: SVINCOLO PARZIALE DI PROVA
B15: =IFERROR(IF($A15="","",LEFT($A15,FIND(" | ",$A15)-1)),"") | C15: =IFERROR(IF($A15="","",MID($A15,FIND(" | ",$A15)+3,FIND(" | ",$A15,FIND(" | ",$A15)+3)-FIND(" | ",$A15)-3)),"") | D15: =IFERROR(IF($A15="","",RIGHT($A15,LEN($A15)-FIND(" | ",$A15,FIND(" | ",$A15)+3)-2)),"") | M15: =IF($B15="","",SUM($J15,-$K15,$L15))
B16: =IFERROR(IF($A16="","",LEFT($A16,FIND(" | ",$A16)-1)),"") | C16: =IFERROR(IF($A16="","",MID($A16,FIND(" | ",$A16)+3,FIND(" | ",$A16,FIND(" | ",$A16)+3)-FIND(" | ",$A16)-3)),"") | D16: =IFERROR(IF($A16="","",RIGHT($A16,LEN($A16)-FIND(" | ",$A16,FIND(" | ",$A16)+3)-2)),"") | M16: =IF($B16="","",SUM($J16,-$K16,$L16))
B17: =IFERROR(IF($A17="","",LEFT($A17,FIND(" | ",$A17)-1)),"") | C17: =IFERROR(IF($A17="","",MID($A17,FIND(" | ",$A17)+3,FIND(" | ",$A17,FIND(" | ",$A17)+3)-FIND(" | ",$A17)-3)),"") | D17: =IFERROR(IF($A17="","",RIGHT($A17,LEN($A17)-FIND(" | ",$A17,FIND(" | ",$A17)+3)-2)),"") | M17: =IF($B17="","",SUM($J17,-$K17,$L17))
B18: =IFERROR(IF($A18="","",LEFT($A18,FIND(" | ",$A18)-1)),"") | C18: =IFERROR(IF($A18="","",MID($A18,FIND(" | ",$A18)+3,FIND(" | ",$A18,FIND(" | ",$A18)+3)-FIND(" | ",$A18)-3)),"") | D18: =IFERROR(IF($A18="","",RIGHT($A18,LEN($A18)-FIND(" | ",$A18,FIND(" | ",$A18)+3)-2)),"") | M18: =IF($B18="","",SUM($J18,-$K18,$L18))
B19: =IFERROR(IF($A19="","",LEFT($A19,FIND(" | ",$A19)-1)),"") | C19: =IFERROR(IF($A19="","",MID($A19,FIND(" | ",$A19)+3,FIND(" | ",$A19,FIND(" | ",$A19)+3)-FIND(" | ",$A19)-3)),"") | D19: =IFERROR(IF($A19="","",RIGHT($A19,LEN($A19)-FIND(" | ",$A19,FIND(" | ",$A19)+3)-2)),"") | M19: =IF($B19="","",SUM($J19,-$K19,$L19))
B20: =IFERROR(IF($A20="","",LEFT($A20,FIND(" | ",$A20)-1)),"") | C20: =IFERROR(IF($A20="","",MID($A20,FIND(" | ",$A20)+3,FIND(" | ",$A20,FIND(" | ",$A20)+3)-FIND(" | ",$A20)-3)),"") | D20: =IFERROR(IF($A20="","",RIGHT($A20,LEN($A20)-FIND(" | ",$A20,FIND(" | ",$A20)+3)-2)),"") | M20: =IF($B20="","",SUM($J20,-$K20,$L20))
B21: =IFERROR(IF($A21="","",LEFT($A21,FIND(" | ",$A21)-1)),"") | C21: =IFERROR(IF($A21="","",MID($A21,FIND(" | ",$A21)+3,FIND(" | ",$A21,FIND(" | ",$A21)+3)-FIND(" | ",$A21)-3)),"") | D21: =IFERROR(IF($A21="","",RIGHT($A21,LEN($A21)-FIND(" | ",$A21,FIND(" | ",$A21)+3)-2)),"") | M21: =IF($B21="","",SUM($J21,-$K21,$L21))
B22: =IFERROR(IF($A22="","",LEFT($A22,FIND(" | ",$A22)-1)),"") | C22: =IFERROR(IF($A22="","",MID($A22,FIND(" | ",$A22)+3,FIND(" | ",$A22,FIND(" | ",$A22)+3)-FIND(" | ",$A22)-3)),"") | D22: =IFERROR(IF($A22="","",RIGHT($A22,LEN($A22)-FIND(" | ",$A22,FIND(" | ",$A22)+3)-2)),"") | M22: =IF($B22="","",SUM($J22,-$K22,$L22))
B23: =IFERROR(IF($A23="","",LEFT($A23,FIND(" | ",$A23)-1)),"") | C23: =IFERROR(IF($A23="","",MID($A23,FIND(" | ",$A23)+3,FIND(" | ",$A23,FIND(" | ",$A23)+3)-FIND(" | ",$A23)-3)),"") | D23: =IFERROR(IF($A23="","",RIGHT($A23,LEN($A23)-FIND(" | ",$A23,FIND(" | ",$A23)+3)-2)),"") | M23: =IF($B23="","",SUM($J23,-$K23,$L23))
B24: =IFERROR(IF($A24="","",LEFT($A24,FIND(" | ",$A24)-1)),"") | C24: =IFERROR(IF($A24="","",MID($A24,FIND(" | ",$A24)+3,FIND(" | ",$A24,FIND(" | ",$A24)+3)-FIND(" | ",$A24)-3)),"") | D24: =IFERROR(IF($A24="","",RIGHT($A24,LEN($A24)-FIND(" | ",$A24,FIND(" | ",$A24)+3)-2)),"") | M24: =IF($B24="","",SUM($J24,-$K24,$L24))
B25: =IFERROR(IF($A25="","",LEFT($A25,FIND(" | ",$A25)-1)),"") | C25: =IFERROR(IF($A25="","",MID($A25,FIND(" | ",$A25)+3,FIND(" | ",$A25,FIND(" | ",$A25)+3)-FIND(" | ",$A25)-3)),"") | D25: =IFERROR(IF($A25="","",RIGHT($A25,LEN($A25)-FIND(" | ",$A25,FIND(" | ",$A25)+3)-2)),"") | M25: =IF($B25="","",SUM($J25,-$K25,$L25))
B26: =IFERROR(IF($A26="","",LEFT($A26,FIND(" | ",$A26)-1)),"") | C26: =IFERROR(IF($A26="","",MID($A26,FIND(" | ",$A26)+3,FIND(" | ",$A26,FIND(" | ",$A26)+3)-FIND(" | ",$A26)-3)),"") | D26: =IFERROR(IF($A26="","",RIGHT($A26,LEN($A26)-FIND(" | ",$A26,FIND(" | ",$A26)+3)-2)),"") | M26: =IF($B26="","",SUM($J26,-$K26,$L26))
... B4206: =IFERROR(IF($A4206="","",LEFT($A4206,FIND(" | ",$A4206)-1)),"") | C4206: =IFERROR(IF($A4206="","",MID($A4206,FIND(" | ",$A4206)+3,FIND(" | ",$A4206,FIND(" | ",$A4206)+3)-FIND(" | ",$A4206)-3)),"") | D4206: =IFERROR(IF($A4206="","",RIGHT($A4206,LEN($A4206)-FIND(" | ",$A4206,FIND(" | ",$A4206)+3)-2)),"") | M4206: =IF($B4206="","",SUM($J4206,-$K4206,$L4206))

Sheet COSTI DIRETTI
A1: COSTI DIRETTI 2026 — REV.14
A2: Registrare esclusivamente i costi specifici della commessa non già assorbiti dal costo orario aziendale.
G3: TOTALE COSTI | H3: =SUM($H$6:$H$505) -> 38308 | I3: ULTIMA DATA | J3: =IF(COUNT($A$6:$A$505)=0,"",MAX($A$6:$A$505)) -> 46254
A5: DATA COSTO | B5: COMMESSA (CODICE | CLIENTE | CANTIERE) | C5: CODICE COMMESSA | D5: CLIENTE | E5: CANTIERE | F5: MACRO-CATEGORIA DA ANALISI | G5: DESCRIZIONE | H5: IMPORTO | I5: FORNITORE / DOCUMENTO | J5: NOTE
A6: 46215 | B6: C042 | CARRON BAU | MURATURE IN LATERIZIO C/O COSMO SPA - PESCHIERA DEL GARDA | C6: =IFERROR(IF($B6="","",LEFT($B6,FIND(" | ",$B6)-1)),"") -> C042 | D6: =IFERROR(IF($B6="","",MID($B6,FIND(" | ",$B6)+3,FIND(" | ",$B6,FIND(" | ",$B6)+3)-FIND(" | ",$B6)-3)),"") -> CARRON BAU | E6: =IFERROR(IF($B6="","",RIGHT($B6,LEN($B6)-FIND(" | ",$B6,FIND(" | ",$B6)+3)-2)),"") -> MURATURE IN LATERIZIO C/O COSMO SPA - PESCHIERA DEL GARDA | F6: Materiali e attrezzature | G6: Laterizi e malte | H6: 5000 | I6: Fornitore di prova | J6: VALORE DIMOSTRATIVO
A7: 46227 | B7: C042 | CARRON BAU | MURATURE IN LATERIZIO C/O COSMO SPA - PESCHIERA DEL GARDA | C7: =IFERROR(IF($B7="","",LEFT($B7,FIND(" | ",$B7)-1)),"") -> C042 | D7: =IFERROR(IF($B7="","",MID($B7,FIND(" | ",$B7)+3,FIND(" | ",$B7,FIND(" | ",$B7)+3)-FIND(" | ",$B7)-3)),"") -> CARRON BAU | E7: =IFERROR(IF($B7="","",RIGHT($B7,LEN($B7)-FIND(" | ",$B7,FIND(" | ",$B7)+3)-2)),"") -> MURATURE IN LATERIZIO C/O COSMO SPA - PESCHIERA DEL GARDA | F7: Materiali e attrezzature | G7: Piattaforma dedicata | H7: 2000 | I7: Noleggio di prova | J7: VALORE DIMOSTRATIVO
A8: 46239 | B8: C042 | CARRON BAU | MURATURE IN LATERIZIO C/O COSMO SPA - PESCHIERA DEL GARDA | C8: =IFERROR(IF($B8="","",LEFT($B8,FIND(" | ",$B8)-1)),"") -> C042 | D8: =IFERROR(IF($B8="","",MID($B8,FIND(" | ",$B8)+3,FIND(" | ",$B8,FIND(" | ",$B8)+3)-FIND(" | ",$B8)-3)),"") -> CARRON BAU | E8: =IFERROR(IF($B8="","",RIGHT($B8,LEN($B8)-FIND(" | ",$B8,FIND(" | ",$B8)+3)-2)),"") -> MURATURE IN LATERIZIO C/O COSMO SPA - PESCHIERA DEL GARDA | F8: Materiali e attrezzature | G8: Trasporto straordinario | H8: 1000 | I8: Documento di prova | J8: VALORE DIMOSTRATIVO
A9: 46254 | B9: C042 | CARRON BAU | MURATURE IN LATERIZIO C/O COSMO SPA - PESCHIERA DEL GARDA | C9: =IFERROR(IF($B9="","",LEFT($B9,FIND(" | ",$B9)-1)),"") -> C042 | D9: =IFERROR(IF($B9="","",MID($B9,FIND(" | ",$B9)+3,FIND(" | ",$B9,FIND(" | ",$B9)+3)-FIND(" | ",$B9)-3)),"") -> CARRON BAU | E9: =IFERROR(IF($B9="","",RIGHT($B9,LEN($B9)-FIND(" | ",$B9,FIND(" | ",$B9)+3)-2)),"") -> MURATURE IN LATERIZIO C/O COSMO SPA - PESCHIERA DEL GARDA | F9: Materiali e attrezzature | G9: Fornitura aggiuntiva di prova | H9: 24308 | I9: Fornitore di prova | J9: VALORE DIMOSTRATIVO PER TEST SFORAMENTO
A10: 46042 | B10: TEST10 | COMMESSA DIMOSTRATIVA | TEST REV.10 - PERDITE SAL E COSTI MENSILI | C10: =IFERROR(IF($B10="","",LEFT($B10,FIND(" | ",$B10)-1)),"") -> TEST10 | D10: =IFERROR(IF($B10="","",MID($B10,FIND(" | ",$B10)+3,FIND(" | ",$B10,FIND(" | ",$B10)+3)-FIND(" | ",$B10)-3)),"") -> COMMESSA DIMOSTRATIVA | E10: =IFERROR(IF($B10="","",RIGHT($B10,LEN($B10)-FIND(" | ",$B10,FIND(" | ",$B10)+3)-2)),"") -> TEST REV.10 - PERDITE SAL E COSTI MENSILI | F10: Materiali e attrezzature | G10: Costo diretto test gennaio | H10: 1000
A11: 46073 | B11: TEST10 | COMMESSA DIMOSTRATIVA | TEST REV.10 - PERDITE SAL E COSTI MENSILI | C11: =IFERROR(IF($B11="","",LEFT($B11,FIND(" | ",$B11)-1)),"") -> TEST10 | D11: =IFERROR(IF($B11="","",MID($B11,FIND(" | ",$B11)+3,FIND(" | ",$B11,FIND(" | ",$B11)+3)-FIND(" | ",$B11)-3)),"") -> COMMESSA DIMOSTRATIVA | E11: =IFERROR(IF($B11="","",RIGHT($B11,LEN($B11)-FIND(" | ",$B11,FIND(" | ",$B11)+3)-2)),"") -> TEST REV.10 - PERDITE SAL E COSTI MENSILI | F11: Materiali e attrezzature | G11: Costo diretto test febbraio | H11: 2000
A12: 46132 | B12: TEST10 | COMMESSA DIMOSTRATIVA | TEST REV.10 - PERDITE SAL E COSTI MENSILI | C12: =IFERROR(IF($B12="","",LEFT($B12,FIND(" | ",$B12)-1)),"") -> TEST10 | D12: =IFERROR(IF($B12="","",MID($B12,FIND(" | ",$B12)+3,FIND(" | ",$B12,FIND(" | ",$B12)+3)-FIND(" | ",$B12)-3)),"") -> COMMESSA DIMOSTRATIVA | E12: =IFERROR(IF($B12="","",RIGHT($B12,LEN($B12)-FIND(" | ",$B12,FIND(" | ",$B12)+3)-2)),"") -> TEST REV.10 - PERDITE SAL E COSTI MENSILI | F12: Materiali e attrezzature | G12: Costo diretto test aprile senza ore | H12: 3000
C13: =IFERROR(IF($B13="","",LEFT($B13,FIND(" | ",$B13)-1)),"") | D13: =IFERROR(IF($B13="","",MID($B13,FIND(" | ",$B13)+3,FIND(" | ",$B13,FIND(" | ",$B13)+3)-FIND(" | ",$B13)-3)),"") | E13: =IFERROR(IF($B13="","",RIGHT($B13,LEN($B13)-FIND(" | ",$B13,FIND(" | ",$B13)+3)-2)),"")
C14: =IFERROR(IF($B14="","",LEFT($B14,FIND(" | ",$B14)-1)),"") | D14: =IFERROR(IF($B14="","",MID($B14,FIND(" | ",$B14)+3,FIND(" | ",$B14,FIND(" | ",$B14)+3)-FIND(" | ",$B14)-3)),"") | E14: =IFERROR(IF($B14="","",RIGHT($B14,LEN($B14)-FIND(" | ",$B14,FIND(" | ",$B14)+3)-2)),"")
C15: =IFERROR(IF($B15="","",LEFT($B15,FIND(" | ",$B15)-1)),"") | D15: =IFERROR(IF($B15="","",MID($B15,FIND(" | ",$B15)+3,FIND(" | ",$B15,FIND(" | ",$B15)+3)-FIND(" | ",$B15)-3)),"") | E15: =IFERROR(IF($B15="","",RIGHT($B15,LEN($B15)-FIND(" | ",$B15,FIND(" | ",$B15)+3)-2)),"")
C16: =IFERROR(IF($B16="","",LEFT($B16,FIND(" | ",$B16)-1)),"") | D16: =IFERROR(IF($B16="","",MID($B16,FIND(" | ",$B16)+3,FIND(" | ",$B16,FIND(" | ",$B16)+3)-FIND(" | ",$B16)-3)),"") | E16: =IFERROR(IF($B16="","",RIGHT($B16,LEN($B16)-FIND(" | ",$B16,FIND(" | ",$B16)+3)-2)),"")
C17: =IFERROR(IF($B17="","",LEFT($B17,FIND(" | ",$B17)-1)),"") | D17: =IFERROR(IF($B17="","",MID($B17,FIND(" | ",$B17)+3,FIND(" | ",$B17,FIND(" | ",$B17)+3)-FIND(" | ",$B17)-3)),"") | E17: =IFERROR(IF($B17="","",RIGHT($B17,LEN($B17)-FIND(" | ",$B17,FIND(" | ",$B17)+3)-2)),"")
C18: =IFERROR(IF($B18="","",LEFT($B18,FIND(" | ",$B18)-1)),"") | D18: =IFERROR(IF($B18="","",MID($B18,FIND(" | ",$B18)+3,FIND(" | ",$B18,FIND(" | ",$B18)+3)-FIND(" | ",$B18)-3)),"") | E18: =IFERROR(IF($B18="","",RIGHT($B18,LEN($B18)-FIND(" | ",$B18,FIND(" | ",$B18)+3)-2)),"")
C19: =IFERROR(IF($B19="","",LEFT($B19,FIND(" | ",$B19)-1)),"") | D19: =IFERROR(IF($B19="","",MID($B19,FIND(" | ",$B19)+3,FIND(" | ",$B19,FIND(" | ",$B19)+3)-FIND(" | ",$B19)-3)),"") | E19: =IFERROR(IF($B19="","",RIGHT($B19,LEN($B19)-FIND(" | ",$B19,FIND(" | ",$B19)+3)-2)),"")
C20: =IFERROR(IF($B20="","",LEFT($B20,FIND(" | ",$B20)-1)),"") | D20: =IFERROR(IF($B20="","",MID($B20,FIND(" | ",$B20)+3,FIND(" | ",$B20,FIND(" | ",$B20)+3)-FIND(" | ",$B20)-3)),"") | E20: =IFERROR(IF($B20="","",RIGHT($B20,LEN($B20)-FIND(" | ",$B20,FIND(" | ",$B20)+3)-2)),"")
C21: =IFERROR(IF($B21="","",LEFT($B21,FIND(" | ",$B21)-1)),"") | D21: =IFERROR(IF($B21="","",MID($B21,FIND(" | ",$B21)+3,FIND(" | ",$B21,FIND(" | ",$B21)+3)-FIND(" | ",$B21)-3)),"") | E21: =IFERROR(IF($B21="","",RIGHT($B21,LEN($B21)-FIND(" | ",$B21,FIND(" | ",$B21)+3)-2)),"")
C22: =IFERROR(IF($B22="","",LEFT($B22,FIND(" | ",$B22)-1)),"") | D22: =IFERROR(IF($B22="","",MID($B22,FIND(" | ",$B22)+3,FIND(" | ",$B22,FIND(" | ",$B22)+3)-FIND(" | ",$B22)-3)),"") | E22: =IFERROR(IF($B22="","",RIGHT($B22,LEN($B22)-FIND(" | ",$B22,FIND(" | ",$B22)+3)-2)),"")
C23: =IFERROR(IF($B23="","",LEFT($B23,FIND(" | ",$B23)-1)),"") | D23: =IFERROR(IF($B23="","",MID($B23,FIND(" | ",$B23)+3,FIND(" | ",$B23,FIND(" | ",$B23)+3)-FIND(" | ",$B23)-3)),"") | E23: =IFERROR(IF($B23="","",RIGHT($B23,LEN($B23)-FIND(" | ",$B23,FIND(" | ",$B23)+3)-2)),"")
C24: =IFERROR(IF($B24="","",LEFT($B24,FIND(" | ",$B24)-1)),"") | D24: =IFERROR(IF($B24="","",MID($B24,FIND(" | ",$B24)+3,FIND(" | ",$B24,FIND(" | ",$B24)+3)-FIND(" | ",$B24)-3)),"") | E24: =IFERROR(IF($B24="","",RIGHT($B24,LEN($B24)-FIND(" | ",$B24,FIND(" | ",$B24)+3)-2)),"")
... C505: =IFERROR(IF($B505="","",LEFT($B505,FIND(" | ",$B505)-1)),"") | D505: =IFERROR(IF($B505="","",MID($B505,FIND(" | ",$B505)+3,FIND(" | ",$B505,FIND(" | ",$B505)+3)-FIND(" | ",$B505)-3)),"") | E505: =IFERROR(IF($B505="","",RIGHT($B505,LEN($B505)-FIND(" | ",$B505,FIND(" | ",$B505)+3)-2)),"")

Sheet CANTIERI
A1: CONTROLLO ECONOMICO E PRODUTTIVO CANTIERI 2026 — REV.14
A2: SELEZIONA COMMESSA | D2: CONTRATTO AGGIORNATO | G2: PERDITE SAL ACCETTATE | J2: VALORE RECUPERABILE | M2: SAL MATURATO | P2: FATTURATO LORDO | S2: SAL NON FATTURATO | V2: RESIDUO LAVORI EFFETTIVO | AA2: MESE | AB2: COSTO MESE | AC2: COSTO CUMULATO
A3: TUTTE | D3: =IF($A$3="TUTTE",SUBTOTAL(109,$J$9:$J$308),IFERROR(INDEX($J$9:$J$308,MATCH($A$3,$C$9:$C$308,0)),0)) -> 425819.41 | G3: =IF($A$3="TUTTE",SUBTOTAL(109,$V$9:$V$308),IFERROR(INDEX($V$9:$V$308,MATCH($A$3,$C$9:$C$308,0)),0)) -> 10000 | J3: =IF($A$3="TUTTE",SUBTOTAL(109,$W$9:$W$308),IFERROR(INDEX($W$9:$W$308,MATCH($A$3,$C$9:$C$308,0)),0)) -> 417819.41 | M3: =IF($A$3="TUTTE",SUBTOTAL(109,$K$9:$K$308),IFERROR(INDEX($K$9:$K$308,MATCH($A$3,$C$9:$C$308,0)),0)) -> 130541.8 | P3: =IF($A$3="TUTTE",SUBTOTAL(109,$L$9:$L$308),IFERROR(INDEX($L$9:$L$308,MATCH($A$3,$C$9:$C$308,0)),0)) -> 134541.8 | S3: =IF($A$3="TUTTE",SUBTOTAL(109,$M$9:$M$308),IFERROR(INDEX($M$9:$M$308,MATCH($A$3,$C$9:$C$308,0)),0)) -> 11000 | V3: =IF($A$3="TUTTE",SUBTOTAL(109,$N$9:$N$308),IFERROR(INDEX($N$9:$N$308,MATCH($A$3,$C$9:$C$308,0)),0)) -> 330048.51 | AA3: Gennaio | AB3: =IF($A$3="","",IF($A$3="TUTTE",SUMIFS('MOVIMENTI 2026'!$N$7:$N$4206,'MOVIMENTI 2026'!$E$7:$E$4206,">="&DATE(PARAMETRI!$B$11,1,1),'MOVIMENTI 2026'!$E$7:$E$4206,"<"&DATE(PARAMETRI!$B$11,2,1))*PARAMETRI!$B$4+SUMIFS('COSTI DIRETTI'!$H$6:$H$505,'COSTI DIRETTI'!$A$6:$A$505,">="&DATE(PARAMETRI!$B$11,1,1),'COSTI DIRETTI'!$A$6:$A$505,"<"&DATE(PARAMETRI!$B$11,2,1)),SUMIFS('MOVIMENTI 2026'!$N$7:$N$4206,'MOVIMENTI 2026'!$B$7:$B$4206,$A$3,'MOVIMENTI 2026'!$E$7:$E$4206,">="&DATE(PARAMETRI!$B$11,1,1),'MOVIMENTI 2026'!$E$7:$E$4206,"<"&DATE(PARAMETRI!$B$11,2,1))*PARAMETRI!$B$4+SUMIFS('COSTI DIRETTI'!$H$6:$H$505,'COSTI DIRETTI'!$C$6:$C$505,$A$3,'COSTI DIRETTI'!$A$6:$A$505,">="&DATE(PARAMETRI!$B$11,1,1),'COSTI DIRETTI'!$A$6:$A$505,"<"&DATE(PARAMETRI!$B$11,2,1)))) -> 5579 | AC3: =IF($A$3="","",$AB3) -> 5579
A4: RESIDUO DA FATTURARE | D4: FATTURATO OLTRE RECUPERABILE | G4: RITENUTE DA SBLOCCARE | J4: COSTO EFFETTIVO CUMULATO | M4: STATO / ALLERTA | P4: AGGIORNATO AL | S4: CANTIERI CRITICI | V4: CANTIERI IN ATTENZIONE | AA4: Febbraio | AB4: =IF($A$3="","",IF($A$3="TUTTE",SUMIFS('MOVIMENTI 2026'!$N$7:$N$4206,'MOVIMENTI 2026'!$E$7:$E$4206,">="&DATE(PARAMETRI!$B$11,2,1),'MOVIMENTI 2026'!$E$7:$E$4206,"<"&DATE(PARAMETRI!$B$11,3,1))*PARAMETRI!$B$4+SUMIFS('COSTI DIRETTI'!$H$6:$H$505,'COSTI DIRETTI'!$A$6:$A$505,">="&DATE(PARAMETRI!$B$11,2,1),'COSTI DIRETTI'!$A$6:$A$505,"<"&DATE(PARAMETRI!$B$11,3,1)),SUMIFS('MOVIMENTI 2026'!$N$7:$N$4206,'MOVIMENTI 2026'!$B$7:$B$4206,$A$3,'MOVIMENTI 2026'!$E$7:$E$4206,">="&DATE(PARAMETRI!$B$11,2,1),'MOVIMENTI 2026'!$E$7:$E$4206,"<"&DATE(PARAMETRI!$B$11,3,1))*PARAMETRI!$B$4+SUMIFS('COSTI DIRETTI'!$H$6:$H$505,'COSTI DIRETTI'!$C$6:$C$505,$A$3,'COSTI DIRETTI'!$A$6:$A$505,">="&DATE(PARAMETRI!$B$11,2,1),'COSTI DIRETTI'!$A$6:$A$505,"<"&DATE(PARAMETRI!$B$11,3,1)))) -> 7494.8 | AC4: =IF($A$3="","",$AC3+$AB4) -> 13073.8
A5: =IF($A$3="TUTTE",SUBTOTAL(109,$BE$9:$BE$308),IFERROR(INDEX($BE$9:$BE$308,MATCH($A$3,$C$9:$C$308,0)),0)) -> 326048.51 | D5: =IF($A$3="TUTTE",SUBTOTAL(109,$BF$9:$BF$308),IFERROR(INDEX($BF$9:$BF$308,MATCH($A$3,$C$9:$C$308,0)),0)) -> 0 | G5: =IF($A$3="TUTTE",SUBTOTAL(109,$O$9:$O$308),IFERROR(INDEX($O$9:$O$308,MATCH($A$3,$C$9:$C$308,0)),0)) -> 3020.46 | J5: =IF($A$3="TUTTE",SUBTOTAL(109,$U$9:$U$308),IFERROR(INDEX($U$9:$U$308,MATCH($A$3,$C$9:$C$308,0)),0)) -> 146627.4 | M5: =IF($A$3="TUTTE","PORTAFOGLIO COMPLESSIVO",IFERROR(INDEX($I$9:$I$308,MATCH($A$3,$C$9:$C$308,0))&" — "&INDEX($A$9:$A$308,MATCH($A$3,$C$9:$C$308,0)),"CODICE NON TROVATO")) -> PORTAFOGLIO COMPLESSIVO | P5: =IF($A$3="TUTTE",IF(COUNT($Y$9:$Y$308)=0,"",MAX($Y$9:$Y$308)),IFERROR(IF(INDEX($Y$9:$Y$308,MATCH($A$3,$C$9:$C$308,0))=0,"",INDEX($Y$9:$Y$308,MATCH($A$3,$C$9:$C$308,0))),"")) -> 46259 | S5: =IF($A$3="TUTTE",SUBTOTAL(109,$BT$9:$BT$308),IF(IFERROR(INDEX($A$9:$A$308,MATCH($A$3,$C$9:$C$308,0)),"")="CRITICO",1,0)) -> 1 | V5: =IF($A$3="TUTTE",SUBTOTAL(109,$BU$9:$BU$308),IF(IFERROR(INDEX($A$9:$A$308,MATCH($A$3,$C$9:$C$308,0)),"")="ATTENZIONE",1,0)) -> 3 | AA5: Marzo | AB5: =IF($A$3="","",IF($A$3="TUTTE",SUMIFS('MOVIMENTI 2026'!$N$7:$N$4206,'MOVIMENTI 2026'!$E$7:$E$4206,">="&DATE(PARAMETRI!$B$11,3,1),'MOVIMENTI 2026'!$E$7:$E$4206,"<"&DATE(PARAMETRI!$B$11,4,1))*PARAMETRI!$B$4+SUMIFS('COSTI DIRETTI'!$H$6:$H$505,'COSTI DIRETTI'!$A$6:$A$505,">="&DATE(PARAMETRI!$B$11,3,1),'COSTI DIRETTI'!$A$6:$A$505,"<"&DATE(PARAMETRI!$B$11,4,1)),SUMIFS('MOVIMENTI 2026'!$N$7:$N$4206,'MOVIMENTI 2026'!$B$7:$B$4206,$A$3,'MOVIMENTI 2026'!$E$7:$E$4206,">="&DATE(PARAMETRI!$B$11,3,1),'MOVIMENTI 2026'!$E$7:$E$4206,"<"&DATE(PARAMETRI!$B$11,4,1))*PARAMETRI!$B$4+SUMIFS('COSTI DIRETTI'!$H$6:$H$505,'COSTI DIRETTI'!$C$6:$C$505,$A$3,'COSTI DIRETTI'!$A$6:$A$505,">="&DATE(PARAMETRI!$B$11,3,1),'COSTI DIRETTI'!$A$6:$A$505,"<"&DATE(PARAMETRI!$B$11,4,1)))) -> 3663.2 | AC5: =IF($A$3="","",$AC4+$AB5) -> 16737
A6: Giallo = selezione/input • Azzurro = calcolo automatico • CANTIERI mostra saldi al 31/12/2025 + movimenti 2026 • AGGIORNATO AL è una data manuale per singola commessa. | AA6: Aprile | AB6: =IF($A$3="","",IF($A$3="TUTTE",SUMIFS('MOVIMENTI 2026'!$N$7:$N$4206,'MOVIMENTI 2026'!$E$7:$E$4206,">="&DATE(PARAMETRI!$B$11,4,1),'MOVIMENTI 2026'!$E$7:$E$4206,"<"&DATE(PARAMETRI!$B$11,5,1))*PARAMETRI!$B$4+SUMIFS('COSTI DIRETTI'!$H$6:$H$505,'COSTI DIRETTI'!$A$6:$A$505,">="&DATE(PARAMETRI!$B$11,4,1),'COSTI DIRETTI'!$A$6:$A$505,"<"&DATE(PARAMETRI!$B$11,5,1)),SUMIFS('MOVIMENTI 2026'!$N$7:$N$4206,'MOVIMENTI 2026'!$B$7:$B$4206,$A$3,'MOVIMENTI 2026'!$E$7:$E$4206,">="&DATE(PARAMETRI!$B$11,4,1),'MOVIMENTI 2026'!$E$7:$E$4206,"<"&DATE(PARAMETRI!$B$11,5,1))*PARAMETRI!$B$4+SUMIFS('COSTI DIRETTI'!$H$6:$H$505,'COSTI DIRETTI'!$C$6:$C$505,$A$3,'COSTI DIRETTI'!$A$6:$A$505,">="&DATE(PARAMETRI!$B$11,4,1),'COSTI DIRETTI'!$A$6:$A$505,"<"&DATE(PARAMETRI!$B$11,5,1)))) -> 3000 | AC6: =IF($A$3="","",$AC5+$AB6) -> 19737
A7: ALLERTE | C7: IDENTIFICAZIONE | J7: CONTRATTO / SAL | P7: TEMPO | R7: ORE / PRODUTTIVITÀ | T7: COSTI DIRETTI / CONSUNTIVO | V7: PERDITE / RECUPERABILE | X7: AZIONI | Y7: CONTROLLO | AA7: Maggio | AB7: =IF($A$3="","",IF($A$3="TUTTE",SUMIFS('MOVIMENTI 2026'!$N$7:$N$4206,'MOVIMENTI 2026'!$E$7:$E$4206,">="&DATE(PARAMETRI!$B$11,5,1),'MOVIMENTI 2026'!$E$7:$E$4206,"<"&DATE(PARAMETRI!$B$11,6,1))*PARAMETRI!$B$4+SUMIFS('COSTI DIRETTI'!$H$6:$H$505,'COSTI DIRETTI'!$A$6:$A$505,">="&DATE(PARAMETRI!$B$11,5,1),'COSTI DIRETTI'!$A$6:$A$505,"<"&DATE(PARAMETRI!$B$11,6,1)),SUMIFS('MOVIMENTI 2026'!$N$7:$N$4206,'MOVIMENTI 2026'!$B$7:$B$4206,$A$3,'MOVIMENTI 2026'!$E$7:$E$4206,">="&DATE(PARAMETRI!$B$11,5,1),'MOVIMENTI 2026'!$E$7:$E$4206,"<"&DATE(PARAMETRI!$B$11,6,1))*PARAMETRI!$B$4+SUMIFS('COSTI DIRETTI'!$H$6:$H$505,'COSTI DIRETTI'!$C$6:$C$505,$A$3,'COSTI DIRETTI'!$A$6:$A$505,">="&DATE(PARAMETRI!$B$11,5,1),'COSTI DIRETTI'!$A$6:$A$505,"<"&DATE(PARAMETRI!$B$11,6,1)))) -> 0 | AC7: =IF($A$3="","",$AC6+$AB7) -> 19737
A8: ALLERTA | B8: MOTIVO DELL'ALLERTA | C8: CODICE COMMESSA | D8: CLIENTE | E8: DESCRIZIONE | F8: RAMO DI ATTIVITÀ | G8: TECNICO | H8: PREPOSTO | I8: STATO CANTIERE | J8: CONTRATTO AGGIORNATO | K8: SAL MATURATO | L8: FATTURATO LORDO | M8: SAL NON FATTURATO | N8: RESIDUO LAVORI | O8: RITENUTE DA SBLOCCARE | P8: SAL % / TEMPO % / SCOSTAMENTO - RISCHIO RITARDO DELLA COMMESSA | Q8: GIORNI DI RITARDO PRODUTTIVO | R8: ORE PREVISTE / USATE / RESIDUE | S8: % ORE / % SAL / SCOSTAMENTO - RISCHIO CONSUMO ECCESSIVO DI ORE | T8: COSTI DIRETTI: BUDGET / SOSTENUTI / RESIDUO-SFORAMENTO | U8: COSTO EFFETTIVO CUMULATO | V8: PERDITE SAL ACCETTATE | W8: VALORE RECUPERABILE | X8: NOTE / AZIONE | Y8: AGGIORNATO AL | AA8: Giugno | AB8: =IF($A$3="","",IF($A$3="TUTTE",SUMIFS('MOVIMENTI 2026'!$N$7:$N$4206,'MOVIMENTI 2026'!$E$7:$E$4206,">="&DATE(PARAMETRI!$B$11,6,1),'MOVIMENTI 2026'!$E$7:$E$4206,"<"&DATE(PARAMETRI!$B$11,7,1))*PARAMETRI!$B$4+SUMIFS('COSTI DIRETTI'!$H$6:$H$505,'COSTI DIRETTI'!$A$6:$A$505,">="&DATE(PARAMETRI!$B$11,6,1),'COSTI DIRETTI'!$A$6:$A$505,"<"&DATE(PARAMETRI!$B$11,7,1)),SUMIFS('MOVIMENTI 2026'!$N$7:$N$4206,'MOVIMENTI 2026'!$B$7:$B$4206,$A$3,'MOVIMENTI 2026'!$E$7:$E$4206,">="&DATE(PARAMETRI!$B$11,6,1),'MOVIMENTI 2026'!$E$7:$E$4206,"<"&DATE(PARAMETRI!$B$11,7,1))*PARAMETRI!$B$4+SUMIFS('COSTI DIRETTI'!$H$6:$H$505,'COSTI DIRETTI'!$C$6:$C$505,$A$3,'COSTI DIRETTI'!$A$6:$A$505,">="&DATE(PARAMETRI!$B$11,6,1),'COSTI DIRETTI'!$A$6:$A$505,"<"&DATE(PARAMETRI!$B$11,7,1)))) -> 0 | AC8: =IF($A$3="","",$AC7+$AB8) -> 19737
A9: =IFERROR(IF($C9="","",IF(OR($BF9>0,$V9>$J9,AND(ISNUMBER($Q9),$Q9>0),AND($BI9<>"",$BI9<-PARAMETRI!$B$6),AND($BM9<>"",$BM9>=1),AND($BN9<>"",$BN9>PARAMETRI!$B$8),AND(ISNUMBER($BR9),$BR9>0)),"CRITICO",IF(OR($AZ9="",LEFT($C9,5)="TEMP",$BJ9="",$BO9="",ANAGRAFICA!$I6="",ANAGRAFICA!$J6="",$Y9="",AND(OR($I9="Finito ritenute non previste",$I9="Finito con sblocco ritenute",$I9="Finito senza sblocco ritenute"),ANAGRAFICA!$K6=""),OR(AND(ANAGRAFICA!$T6<>"",ANAGRAFICA!$J6<>ANAGRAFICA!$T6,OR(ANAGRAFICA!$R6="",ANAGRAFICA!$R6="Nessuna variazione")),AND(ANAGRAFICA!$J6="",ANAGRAFICA!$R6<>"",ANAGRAFICA!$R6<>"Nessuna variazione")),AND($BI9<>"",$BI9<-PARAMETRI!$B$5),AND($BN9<>"",$BN9>PARAMETRI!$B$7),AND($W9>0,$M9>$W9*PARAMETRI!$B$9),AND($O9>0,OR($I9="Finito ritenute non previste",$I9="Finito con sblocco ritenute",$I9="Finito senza sblocco ritenute")),AND($BA9>0,$BO9>0,$BP9=0),AND(OR($I9="Finito ritenute non previste",$I9="Finito con sblocco ritenute",$I9="Finito senza sblocco ritenute"),$W9>0,$N9>$W9*PARAMETRI!$B$9),$V9>0),"ATTENZIONE","REGOLARE"))),"ATTENZIONE") -> CRITICO | B9: =IFERROR(IF($C9="","",IF($BF9>0,"FATTURATO OLTRE VALORE RECUPERABILE; ","")&IF($V9>$J9,"PERDITE ACCETTATE OLTRE CONTRATTO; ","")&IF($V9>0,"PERDITA SAL ACCETTATA (€ "&TEXT($V9,"#,##0.00")&"); ","")&IF(AND(ISNUMBER($Q9),$Q9>0),"RITARDO PRODUTTIVO ("&TEXT($Q9,"0")&" GG); ","")&IF(AND($BI9<>"",$BI9<-PARAMETRI!$B$5),"AVANZAMENTO PIÙ LENTO DEL TEMPO; ","")&IF(AND($BM9<>"",$BM9>1),"ORE OLTRE BUDGET; ","")&IF(AND($BM9<>"",$BM9=1),"ORE PREVENTIVATE ESAURITE; ","")&IF(AND($BN9<>"",$BN9>PARAMETRI!$B$7),"CONSUMO ORE SUPERIORE ALL'AVANZAMENTO; ","")&IF(AND(ISNUMBER($BR9),$BR9>0),"COSTI DIRETTI OLTRE BUDGET; ","")&IF(AND($W9>0,$M9>$W9*PARAMETRI!$B$9),"SAL MATURATO NON FATTURATO; ","")&IF(AND($O9>0,OR($I9="Finito ritenute non previste",$I9="Finito con sblocco ritenute",$I9="Finito senza sblocco ritenute")),"RITENUTE DA SBLOCCARE; ","")&IF(AND($BA9>0,$BO9>0,$BP9=0),"COSTI DIRETTI NON REGISTRATI; ","")&IF(AND(OR($I9="Finito ritenute non previste",$I9="Finito con sblocco ritenute",$I9="Finito senza sblocco ritenute"),$W9>0,$N9>$W9*PARAMETRI!$B$9),"CANTIERE FINITO CON RESIDUO LAVORI; ","")&IF(AND(OR($I9="Finito ritenute non previste",$I9="Finito con sblocco ritenute",$I9="Finito senza sblocco ritenute"),ANAGRAFICA!$K6=""),"DATA FINE EFFETTIVA MANCANTE; ","")&IF(OR(AND(ANAGRAFICA!$T6<>"",ANAGRAFICA!$J6<>ANAGRAFICA!$T6,OR(ANAGRAFICA!$R6="",ANAGRAFICA!$R6="Nessuna variazione")),AND(ANAGRAFICA!$J6="",ANAGRAFICA!$R6<>"",ANAGRAFICA!$R6<>"Nessuna variazione")),"GESTIONE DATA FINE INCOMPLETA; ","")&IF($Y9="","AGGIORNATO AL MANCANTE; ","")&IF(OR($AZ9="",$BJ9="",$BO9="",ANAGRAFICA!$I6="",ANAGRAFICA!$J6=""),"DATI PREVISIONALI INCOMPLETI; ","")&IF(LEFT($C9,5)="TEMP","CODICE COMMESSA TEMPORANEO; ","")),"DATI INCOMPLETI; ") -> PERDITA SAL ACCETTATA (€ 2000,000); AVANZAMENTO PIÙ LENTO DEL TEMPO; CONSUMO ORE SUPERIORE ALL'AVANZAMENTO; COSTI DIRETTI OLTRE BUDGET; | C9: =IF(ANAGRAFICA!$B6="","",ANAGRAFICA!$B6) -> C042 | D9: =IF($C9="","",ANAGRAFICA!$C6) -> CARRON BAU | E9: =IF($C9="","",ANAGRAFICA!$D6) -> MURATURE IN LATERIZIO C/O COSMO SPA - PESCHIERA DEL GARDA | F9: =IF($C9="","",ANAGRAFICA!$E6) -> MURATURA | G9: =IF($C9="","",ANAGRAFICA!$F6) -> DAVIDE | H9: =IF($C9="","",ANAGRAFICA!$G6) -> AHMET MOUSTAFA | I9: =IF($C9="","",ANAGRAFICA!$L6) -> In corso | J9: =IF($C9="","",$AZ9) -> 143061.41 | K9: =IF($C9="","",$BA9) -> 42770.9 | L9: =IF($C9="","",$BB9) -> 42770.9 | M9: =IF($C9="","",MAX($BA9-$BB9,0)) -> 0 | N9: =IF(OR($C9="",$W9=""),"",MAX($W9-$BA9,0)) -> 98290.51 | O9: =IF($C9="","",MAX($BC9-$BD9,0)) -> 1510.23 | P9: =IF(OR($C9="",$BG9="",$BH9="",$BI9=""),"",TEXT($BG9,"0.0%")&" / "&TEXT($BH9,"0.0%")&" / "&TEXT($BI9,"0.0%")) -> 30% / 100% / -70% | Q9: =IF(OR($C9="",'BUDGET COMMESSA'!$D6="",'BUDGET COMMESSA'!$D6<=0,ANAGRAFICA!$J6=""),"",IF(OR($I9="Finito ritenute non previste",$I9="Finito con sblocco ritenute",$I9="Finito senza sblocco ritenute"),0,IF(AND($BK9>=$BJ9,ANAGRAFICA!$R6="Ritardo produttivo FIDA"),IF(ANAGRAFICA!$T6<>"",MAX(0,ANAGRAFICA!$J6-ANAGRAFICA!$T6),MAX(0,$Y9-ANAGRAFICA!$J6)),0))) -> 0 | R9: =IF(OR($C9="",$BJ9=""),"",TEXT($BJ9,"#,##0.00")&" / "&TEXT($BK9,"#,##0.00")&" / "&TEXT($BL9,"#,##0.00")) -> 1800,000 / 680,000 / 1120,000 | S9: =IF(OR($C9="",$BM9="",$BG9="",$BN9=""),"",TEXT($BM9,"0.0%")&" / "&TEXT($BG9,"0.0%")&" / "&TEXT($BN9,"0.0%")) -> 38% / 30% / 07% | T9: =IF(OR($C9="",$BO9=""),"",IF($BR9>0,"BUDGET € "&TEXT($BO9,"#,##0.00")&" | SOSTENUTI € "&TEXT($BP9,"#,##0.00")&" | SFORAMENTO € "&TEXT($BR9,"#,##0.00"),"BUDGET € "&TEXT($BO9,"#,##0.00")&" | SOSTENUTI € "&TEXT($BP9,"#,##0.00")&" | RESIDUO € "&TEXT($BQ9,"#,##0.00"))) -> BUDGET € 31308,000 | SOSTENUTI € 32308,000 | SFORAMENTO € 1000,000 | U9: =IF($C9="","",$BS9) -> 63445.2 | V9: =IF($C9="","",$BV9) -> 2000 | W9: =IF(OR($C9="",$AZ9=""),"",MAX($AZ9-$BV9,0)) -> 141061.41 | Y9: 46259 | AA9: Luglio | AB9: =IF($A$3="","",IF($A$3="TUTTE",SUMIFS('MOVIMENTI 2026'!$N$7:$N$4206,'MOVIMENTI 2026'!$E$7:$E$4206,">="&DATE(PARAMETRI!$B$11,7,1),'MOVIMENTI 2026'!$E$7:$E$4206,"<"&DATE(PARAMETRI!$B$11,8,1))*PARAMETRI!$B$4+SUMIFS('COSTI DIRETTI'!$H$6:$H$505,'COSTI DIRETTI'!$A$6:$A$505,">="&DATE(PARAMETRI!$B$11,7,1),'COSTI DIRETTI'!$A$6:$A$505,"<"&DATE(PARAMETRI!$B$11,8,1)),SUMIFS('MOVIMENTI 2026'!$N$7:$N$4206,'MOVIMENTI 2026'!$B$7:$B$4206,$A$3,'MOVIMENTI 2026'!$E$7:$E$4206,">="&DATE(PARAMETRI!$B$11,7,1),'MOVIMENTI 2026'!$E$7:$E$4206,"<"&DATE(PARAMETRI!$B$11,8,1))*PARAMETRI!$B$4+SUMIFS('COSTI DIRETTI'!$H$6:$H$505,'COSTI DIRETTI'!$C$6:$C$505,$A$3,'COSTI DIRETTI'!$A$6:$A$505,">="&DATE(PARAMETRI!$B$11,7,1),'COSTI DIRETTI'!$A$6:$A$505,"<"&DATE(PARAMETRI!$B$11,8,1)))) -> 38137.2 | AC9: =IF($A$3="","",$AC8+$AB9) -> 57874.2 | AZ9: =IF($C9="","",ANAGRAFICA!$P6) -> 143061.41 | BA9: =IF($C9="","",SUMIF('MOVIMENTI 2026'!$B$7:$B$4206,$C9,'MOVIMENTI 2026'!$I$7:$I$4206)+SUMIF('SALDI AL 31.12.2025'!$A$6:$A$505,$C9,'SALDI AL 31.12.2025'!$C$6:$C$505)) -> 42770.9 | BB9: =IF($C9="","",SUMIF('MOVIMENTI 2026'!$B$7:$B$4206,$C9,'MOVIMENTI 2026'!$J$7:$J$4206)+SUMIF('SALDI AL 31.12.2025'!$A$6:$A$505,$C9,'SALDI AL 31.12.2025'!$D$6:$D$505)) -> 42770.9 | BC9: =IF($C9="","",SUMIF('MOVIMENTI 2026'!$B$7:$B$4206,$C9,'MOVIMENTI 2026'!$K$7:$K$4206)+SUMIF('SALDI AL 31.12.2025'!$A$6:$A$505,$C9,'SALDI AL 31.12.2025'!$E$6:$E$505)) -> 2010.23 | BD9: =IF($C9="","",SUMIF('MOVIMENTI 2026'!$B$7:$B$4206,$C9,'MOVIMENTI 2026'!$L$7:$L$4206)+SUMIF('SALDI AL 31.12.2025'!$A$6:$A$505,$C9,'SALDI AL 31.12.2025'!$F$6:$F$505)) -> 500 | BE9: =IF(OR($C9="",$W9=""),"",MAX($W9-$BB9,0)) -> 98290.51 | BF9: =IF(OR($C9="",$W9=""),"",MAX($BB9-$W9,0)) -> 0 | BG9: =IF(OR($C9="",$W9<=0),"",$BA9/$W9) -> 0.30320766 | BH9: =IFERROR(IF(OR($C9="",ANAGRAFICA!$I6="",ANAGRAFICA!$J6="",ANAGRAFICA!$J6<=ANAGRAFICA!$I6,$Y9=""),"",IF(OR($I9="Finito ritenute non previste",$I9="Finito con sblocco ritenute",$I9="Finito senza sblocco ritenute"),1,MAX(0,MIN(1,($Y9-ANAGRAFICA!$I6)/(ANAGRAFICA!$J6-ANAGRAFICA!$I6))))),"") -> 1 | BI9: =IF(OR($C9="",$BG9="",$BH9=""),"",$BG9-$BH9) -> -0.69679234 | BJ9: =IFERROR(IF($C9="","",'BUDGET COMMESSA'!$D6),"") -> 1800 | BK9: =IF($C9="","",SUMIF('MOVIMENTI 2026'!$B$7:$B$4206,$C9,'MOVIMENTI 2026'!$N$7:$N$4206)+SUMIF('SALDI AL 31.12.2025'!$A$6:$A$505,$C9,'SALDI AL 31.12.2025'!$H$6:$H$505)) -> 680 | BL9: =IF(OR($C9="",$BJ9=""),"",MAX($BJ9-$BK9,0)) -> 1120 | BM9: =IF(OR($C9="",$BJ9<=0),"",$BK9/$BJ9) -> 0.37777778 | BN9: =IF(OR($C9="",$BM9="",$BG9=""),"",$BM9-$BG9) -> 0.074570118 | BO9: =IFERROR(IF($C9="","",'BUDGET COMMESSA'!$G6),"") -> 31308 | BP9: =IF($C9="","",SUMIF('COSTI DIRETTI'!$C$6:$C$505,$C9,'COSTI DIRETTI'!$H$6:$H$505)+SUMIF('SALDI AL 31.12.2025'!$A$6:$A$505,$C9,'SALDI AL 31.12.2025'!$I$6:$I$505)) -> 32308 | BQ9: =IF(OR($C9="",$BO9=""),"",MAX($BO9-$BP9,0)) -> 0 | BR9: =IF(OR($C9="",$BO9=""),"",MAX($BP9-$BO9,0)) -> 1000 | BS9: =IF($C9="","",$BK9*PARAMETRI!$B$4+$BP9) -> 63445.2 | BT9: =IF($A9="CRITICO",1,0) -> 1 | BU9: =IF($A9="ATTENZIONE",1,0) -> 0 | BV9: =IF($C9="","",SUMIF('MOVIMENTI 2026'!$B$7:$B$4206,$C9,'MOVIMENTI 2026'!$P$7:$P$4206)+SUMIF('SALDI AL 31.12.2025'!$A$6:$A$505,$C9,'SALDI AL 31.12.2025'!$G$6:$G$505)) -> 2000
A10: =IFERROR(IF($C10="","",IF(OR($BF10>0,$V10>$J10,AND(ISNUMBER($Q10),$Q10>0),AND($BI10<>"",$BI10<-PARAMETRI!$B$6),AND($BM10<>"",$BM10>=1),AND($BN10<>"",$BN10>PARAMETRI!$B$8),AND(ISNUMBER($BR10),$BR10>0)),"CRITICO",IF(OR($AZ10="",LEFT($C10,5)="TEMP",$BJ10="",$BO10="",ANAGRAFICA!$I7="",ANAGRAFICA!$J7="",$Y10="",AND(OR($I10="Finito ritenute non previste",$I10="Finito con sblocco ritenute",$I10="Finito senza sblocco ritenute"),ANAGRAFICA!$K7=""),OR(AND(ANAGRAFICA!$T7<>"",ANAGRAFICA!$J7<>ANAGRAFICA!$T7,OR(ANAGRAFICA!$R7="",ANAGRAFICA!$R7="Nessuna variazione")),AND(ANAGRAFICA!$J7="",ANAGRAFICA!$R7<>"",ANAGRAFICA!$R7<>"Nessuna variazione")),AND($BI10<>"",$BI10<-PARAMETRI!$B$5),AND($BN10<>"",$BN10>PARAMETRI!$B$7),AND($W10>0,$M10>$W10*PARAMETRI!$B$9),AND($O10>0,OR($I10="Finito ritenute non previste",$I10="Finito con sblocco ritenute",$I10="Finito senza sblocco ritenute")),AND($BA10>0,$BO10>0,$BP10=0),AND(OR($I10="Finito ritenute non previste",$I10="Finito con sblocco ritenute",$I10="Finito senza sblocco ritenute"),$W10>0,$N10>$W10*PARAMETRI!$B$9),$V10>0),"ATTENZIONE","REGOLARE"))),"ATTENZIONE") -> ATTENZIONE | B10: =IFERROR(IF($C10="","",IF($BF10>0,"FATTURATO OLTRE VALORE RECUPERABILE; ","")&IF($V10>$J10,"PERDITE ACCETTATE OLTRE CONTRATTO; ","")&IF($V10>0,"PERDITA SAL ACCETTATA (€ "&TEXT($V10,"#,##0.00")&"); ","")&IF(AND(ISNUMBER($Q10),$Q10>0),"RITARDO PRODUTTIVO ("&TEXT($Q10,"0")&" GG); ","")&IF(AND($BI10<>"",$BI10<-PARAMETRI!$B$5),"AVANZAMENTO PIÙ LENTO DEL TEMPO; ","")&IF(AND($BM10<>"",$BM10>1),"ORE OLTRE BUDGET; ","")&IF(AND($BM10<>"",$BM10=1),"ORE PREVENTIVATE ESAURITE; ","")&IF(AND($BN10<>"",$BN10>PARAMETRI!$B$7),"CONSUMO ORE SUPERIORE ALL'AVANZAMENTO; ","")&IF(AND(ISNUMBER($BR10),$BR10>0),"COSTI DIRETTI OLTRE BUDGET; ","")&IF(AND($W10>0,$M10>$W10*PARAMETRI!$B$9),"SAL MATURATO NON FATTURATO; ","")&IF(AND($O10>0,OR($I10="Finito ritenute non previste",$I10="Finito con sblocco ritenute",$I10="Finito senza sblocco ritenute")),"RITENUTE DA SBLOCCARE; ","")&IF(AND($BA10>0,$BO10>0,$BP10=0),"COSTI DIRETTI NON REGISTRATI; ","")&IF(AND(OR($I10="Finito ritenute non previste",$I10="Finito con sblocco ritenute",$I10="Finito senza sblocco ritenute"),$W10>0,$N10>$W10*PARAMETRI!$B$9),"CANTIERE FINITO CON RESIDUO LAVORI; ","")&IF(AND(OR($I10="Finito ritenute non previste",$I10="Finito con sblocco ritenute",$I10="Finito senza sblocco ritenute"),ANAGRAFICA!$K7=""),"DATA FINE EFFETTIVA MANCANTE; ","")&IF(OR(AND(ANAGRAFICA!$T7<>"",ANAGRAFICA!$J7<>ANAGRAFICA!$T7,OR(ANAGRAFICA!$R7="",ANAGRAFICA!$R7="Nessuna variazione")),AND(ANAGRAFICA!$J7="",ANAGRAFICA!$R7<>"",ANAGRAFICA!$R7<>"Nessuna variazione")),"GESTIONE DATA FINE INCOMPLETA; ","")&IF($Y10="","AGGIORNATO AL MANCANTE; ","")&IF(OR($AZ10="",$BJ10="",$BO10="",ANAGRAFICA!$I7="",ANAGRAFICA!$J7=""),"DATI PREVISIONALI INCOMPLETI; ","")&IF(LEFT($C10,5)="TEMP","CODICE COMMESSA TEMPORANEO; ","")),"DATI INCOMPLETI; ") -> PERDITA SAL ACCETTATA (€ 1000,000); SAL MATURATO NON FATTURATO; CANTIERE FINITO CON RESIDUO LAVORI; DATA FINE EFFETTIVA MANCANTE; AGGIORNATO AL MANCANTE; | C10: =IF(ANAGRAFICA!$B7="","",ANAGRAFICA!$B7) -> C011 | D10: =IF($C10="","",ANAGRAFICA!$C7) -> CARRON | E10: =IF($C10="","",ANAGRAFICA!$D7) -> ZABARELLA 2023 - COD. CANTIERE 774 | F10: =IF($C10="","",ANAGRAFICA!$E7) -> MURATURA+ECONOMIE | G10: =IF($C10="","",ANAGRAFICA!$F7) -> ALBAN | H10: =IF($C10="","",ANAGRAFICA!$G7) -> NA | I10: =IF($C10="","",ANAGRAFICA!$L7) -> Finito ritenute non previste | J10: =IF($C10="","",$AZ10) -> 182758 | K10: =IF($C10="","",$BA10) -> 20000 | L10: =IF($C10="","",$BB10) -> 9000 | M10: =IF($C10="","",MAX($BA10-$BB10,0)) -> 11000 | N10: =IF(OR($C10="",$W10=""),"",MAX($W10-$BA10,0)) -> 161758 | O10: =IF($C10="","",MAX($BC10-$BD10,0)) -> 0 | P10: =IF(OR($C10="",$BG10="",$BH10="",$BI10=""),"",TEXT($BG10,"0.0%")&" / "&TEXT($BH10,"0.0%")&" / "&TEXT($BI10,"0.0%")) | Q10: =IF(OR($C10="",'BUDGET COMMESSA'!$D7="",'BUDGET COMMESSA'!$D7<=0,ANAGRAFICA!$J7=""),"",IF(OR($I10="Finito ritenute non previste",$I10="Finito con sblocco ritenute",$I10="Finito senza sblocco ritenute"),0,IF(AND($BK10>=$BJ10,ANAGRAFICA!$R7="Ritardo produttivo FIDA"),IF(ANAGRAFICA!$T7<>"",MAX(0,ANAGRAFICA!$J7-ANAGRAFICA!$T7),MAX(0,$Y10-ANAGRAFICA!$J7)),0))) | R10: =IF(OR($C10="",$BJ10=""),"",TEXT($BJ10,"#,##0.00")&" / "&TEXT($BK10,"#,##0.00")&" / "&TEXT($BL10,"#,##0.00")) -> ,000 / ,000 / ,000 | S10: =IF(OR($C10="",$BM10="",$BG10="",$BN10=""),"",TEXT($BM10,"0.0%")&" / "&TEXT($BG10,"0.0%")&" / "&TEXT($BN10,"0.0%")) | T10: =IF(OR($C10="",$BO10=""),"",IF($BR10>0,"BUDGET € "&TEXT($BO10,"#,##0.00")&" | SOSTENUTI € "&TEXT($BP10,"#,##0.00")&" | SFORAMENTO € "&TEXT($BR10,"#,##0.00"),"BUDGET € "&TEXT($BO10,"#,##0.00")&" | SOSTENUTI € "&TEXT($BP10,"#,##0.00")&" | RESIDUO € "&TEXT($BQ10,"#,##0.00"))) -> BUDGET € ,000 | SOSTENUTI € ,000 | RESIDUO € ,000 | U10: =IF($C10="","",$BS10) -> 0 | V10: =IF($C10="","",$BV10) -> 1000 | W10: =IF(OR($C10="",$AZ10=""),"",MAX($AZ10-$BV10,0)) -> 181758 | AA10: Agosto | AB10: =IF($A$3="","",IF($A$3="TUTTE",SUMIFS('MOVIMENTI 2026'!$N$7:$N$4206,'MOVIMENTI 2026'!$E$7:$E$4206,">="&DATE(PARAMETRI!$B$11,8,1),'MOVIMENTI 2026'!$E$7:$E$4206,"<"&DATE(PARAMETRI!$B$11,9,1))*PARAMETRI!$B$4+SUMIFS('COSTI DIRETTI'!$H$6:$H$505,'COSTI DIRETTI'!$A$6:$A$505,">="&DATE(PARAMETRI!$B$11,8,1),'COSTI DIRETTI'!$A$6:$A$505,"<"&DATE(PARAMETRI!$B$11,9,1)),SUMIFS('MOVIMENTI 2026'!$N$7:$N$4206,'MOVIMENTI 2026'!$B$7:$B$4206,$A$3,'MOVIMENTI 2026'!$E$7:$E$4206,">="&DATE(PARAMETRI!$B$11,8,1),'MOVIMENTI 2026'!$E$7:$E$4206,"<"&DATE(PARAMETRI!$B$11,9,1))*PARAMETRI!$B$4+SUMIFS('COSTI DIRETTI'!$H$6:$H$505,'COSTI DIRETTI'!$C$6:$C$505,$A$3,'COSTI DIRETTI'!$A$6:$A$505,">="&DATE(PARAMETRI!$B$11,8,1),'COSTI DIRETTI'!$A$6:$A$505,"<"&DATE(PARAMETRI!$B$11,9,1)))) -> 25308 | AC10: =IF($A$3="","",$AC9+$AB10) -> 83182.2 | AZ10: =IF($C10="","",ANAGRAFICA!$P7) -> 182758 | BA10: =IF($C10="","",SUMIF('MOVIMENTI 2026'!$B$7:$B$4206,$C10,'MOVIMENTI 2026'!$I$7:$I$4206)+SUMIF('SALDI AL 31.12.2025'!$A$6:$A$505,$C10,'SALDI AL 31.12.2025'!$C$6:$C$505)) -> 20000 | BB10: =IF($C10="","",SUMIF('MOVIMENTI 2026'!$B$7:$B$4206,$C10,'MOVIMENTI 2026'!$J$7:$J$4206)+SUMIF('SALDI AL 31.12.2025'!$A$6:$A$505,$C10,'SALDI AL 31.12.2025'!$D$6:$D$505)) -> 9000 | BC10: =IF($C10="","",SUMIF('MOVIMENTI 2026'!$B$7:$B$4206,$C10,'MOVIMENTI 2026'!$K$7:$K$4206)+SUMIF('SALDI AL 31.12.2025'!$A$6:$A$505,$C10,'SALDI AL 31.12.2025'!$E$6:$E$505)) -> 0 | BD10: =IF($C10="","",SUMIF('MOVIMENTI 2026'!$B$7:$B$4206,$C10,'MOVIMENTI 2026'!$L$7:$L$4206)+SUMIF('SALDI AL 31.12.2025'!$A$6:$A$505,$C10,'SALDI AL 31.12.2025'!$F$6:$F$505)) -> 0 | BE10: =IF(OR($C10="",$W10=""),"",MAX($W10-$BB10,0)) -> 172758 | BF10: =IF(OR($C10="",$W10=""),"",MAX($BB10-$W10,0)) -> 0 | BG10: =IF(OR($C10="",$W10<=0),"",$BA10/$W10) -> 0.11003642 | BH10: =IFERROR(IF(OR($C10="",ANAGRAFICA!$I7="",ANAGRAFICA!$J7="",ANAGRAFICA!$J7<=ANAGRAFICA!$I7,$Y10=""),"",IF(OR($I10="Finito ritenute non previste",$I10="Finito con sblocco ritenute",$I10="Finito senza sblocco ritenute"),1,MAX(0,MIN(1,($Y10-ANAGRAFICA!$I7)/(ANAGRAFICA!$J7-ANAGRAFICA!$I7))))),"") | BI10: =IF(OR($C10="",$BG10="",$BH10=""),"",$BG10-$BH10) | BJ10: =IFERROR(IF($C10="","",'BUDGET COMMESSA'!$D7),"") -> 0 | BK10: =IF($C10="","",SUMIF('MOVIMENTI 2026'!$B$7:$B$4206,$C10,'MOVIMENTI 2026'!$N$7:$N$4206)+SUMIF('SALDI AL 31.12.2025'!$A$6:$A$505,$C10,'SALDI AL 31.12.2025'!$H$6:$H$505)) -> 0 | BL10: =IF(OR($C10="",$BJ10=""),"",MAX($BJ10-$BK10,0)) -> 0 | BM10: =IF(OR($C10="",$BJ10<=0),"",$BK10/$BJ10) | BN10: =IF(OR($C10="",$BM10="",$BG10=""),"",$BM10-$BG10) | BO10: =IFERROR(IF($C10="","",'BUDGET COMMESSA'!$G7),"") -> 0 | BP10: =IF($C10="","",SUMIF('COSTI DIRETTI'!$C$6:$C$505,$C10,'COSTI DIRETTI'!$H$6:$H$505)+SUMIF('SALDI AL 31.12.2025'!$A$6:$A$505,$C10,'SALDI AL 31.12.2025'!$I$6:$I$505)) -> 0 | BQ10: =IF(OR($C10="",$BO10=""),"",MAX($BO10-$BP10,0)) -> 0 | BR10: =IF(OR($C10="",$BO10=""),"",MAX($BP10-$BO10,0)) -> 0 | BS10: =IF($C10="","",$BK10*PARAMETRI!$B$4+$BP10) -> 0 | BT10: =IF($A10="CRITICO",1,0) -> 0 | BU10: =IF($A10="ATTENZIONE",1,0) -> 1 | BV10: =IF($C10="","",SUMIF('MOVIMENTI 2026'!$B$7:$B$4206,$C10,'MOVIMENTI 2026'!$P$7:$P$4206)+SUMIF('SALDI AL 31.12.2025'!$A$6:$A$505,$C10,'SALDI AL 31.12.2025'!$G$6:$G$505)) -> 1000
